Workbook

Sheet About
B7: About the company
B8: Oberoi Realty Ltd is a real estate development company, headquartered in Mumbai. It is the part of Oberoi Realty Group, focused on developments in the residential, office space, retail, hospitality, and social infrastructure verticals.
B11: Business Segments
B12: 1) Real Estate (96% in 9M FY25 vs 97% in FY22):
B13: The company is an India’s leading real estate developer, specializing in premium residential, office space, retail, hospitality, and social infrastructure projects. It has completed 50 projects across Mumbai, covering 161 lakh sq ft of developed area.
B16: 2) Hospitality (4% in 9M FY25 vs 3% in FY22)
B17: company operates The Westin Mumbai Garden City, a luxury hotel in Goregaon East. The hotel features 269 rooms, premium amenities, recreational facilities, business services, multiple dining options, etc
B20: Investment Properties
B21: The company’s investment property portfolio comprises 6 commercial properties in Mumbai, including Commerz I, II, III, Oberoi International School (Goregaon & JVLR), and Oberoi Mall, with a total leased carpet area of 25+ lakh sq ft. Rental income from these properties contributed 13% of revenue in 9M FY25 vs 7% in FY24.
B25: Development Properties
B26: The company’s development properties portfolio includes key projects across Mumbai, including Elysian, Jardin, Forestville, Eternia, Enigma, Sky City, and Three Sixty West, with a total carpet area of 1.04 Cr sq ft. As of Q3 FY25, 67.4 lakh sq ft has been booked, while 36.7 lakh sq ft remains in inventory, contributing to a total booking value of Rs. 20,945 Cr.
B30: New Launch
B31: In Oct 2024, the company launched Oberoi Garden City, Thane, spread across 75 acres. The project features luxury homes, the JW Marriott Hotel, a Private Membership Club, and Oberoi International School. The first phase includes 5 towers with 3 BHK and 3 BHK + studio apartments. Bookings for 2 towers reached Rs. 1,348 Cr for 5.65 lakh sq ft in the first 3 days.

Sheet Holdings
B1: Public Holdings | M1: Promoters
B2: Category & Name of the Shareholders | C2: No. of shareholder | D2: No. of fully paid up equity shares held | E2: Total no. shares held | F2: Shareholding % calculated as per SCRR, 1957 As a % of (A+B+C2) | G2: No. of Voting Rights | H2: Total as a % of Total Voting right | I2: Total No. Of shares on fully diluted basis (including warrants, ESOP, Convertible Securities etc.) | J2: Shareholding , as a % assuming full conversion of convertible securities ( as a percentage of diluted share capital)As a % of (A+B+C2) | K2: No. of equity shares held in dematerialized form(Not Applicable) | M2: Category of shareholder | N2: Entity Type | O2: Nos. of shareholders | P2: No. of fully paid up equity shares held | Q2: Total nos. shares held | R2: Shareholding as a % of total no. of shares (calculated as per SCRR, 1957)As a % of (A+B+C2) | S2: Number of Voting Rights held in each class of securities | U2: Number of equity shares held in dematerialized form
B3: Institutions | C3: - | D3: - | E3: - | F3: 0 | G3: - | H3: 0 | I3: - | J3: 0 | K3: - | S3: Class eg: X | T3: Total
B4: B1) Institutions (Domestic) | C4: - | D4: - | E4: - | F4: 0 | G4: - | H4: 0 | I4: - | J4: 0 | K4: - | M4: A5) Indian | O4: - | P4: - | Q4: - | R4: 0 | S4: - | T4: 0 | U4: -
B5: Mutual Funds/ | C5: 51 | D5: 81680997 | E5: 81680997 | F5: 4.24 | G5: 81680997 | H5: 4.24 | I5: 81680997 | J5: 4.24 | K5: 81669827 | M5: A6) Foreign | O5: - | P5: - | Q5: - | R5: 0 | S5: - | T5: 0 | U5: -
B6: Alternate Investment Funds | C6: 24 | D6: 346401 | E6: 346401 | F6: 0.02 | G6: 346401 | H6: 0.02 | I6: 346401 | J6: 0.02 | K6: 346401 | M6: Any Other (specify) | O6: 2 | P6: 1210301580 | Q6: 1210301580 | R6: 62.76 | S6: 1210301580 | T6: 62.76 | U6: 1210301580
B7: Banks | C7: 18 | D7: 956589 | E7: 956589 | F7: 0.05 | G7: 956589 | H7: 0.05 | I7: 956589 | J7: 0.05 | K7: 920569 | M7: NESTLE S.A. | N7: Promoter | O7: 1 | P7: 661027980 | Q7: 661027980 | R7: 34.28 | S7: 661027980 | T7: 34.28 | U7: 661027980
B8: Insurance Companies | C8: 30 | D8: 142059206 | E8: 142059206 | F8: 7.37 | G8: 142059206 | H8: 7.37 | I8: 142059206 | J8: 7.37 | K8: 142058706 | M8: MAGGI ENTERPRISES LTD | N8: Promoter | O8: 1 | P8: 549273600 | Q8: 549273600 | R8: 28.48 | S8: 549273600 | T8: 28.48 | U8: 549273600
B9: LIFE INSURANCE CORPORATION OF INDIA | C9: 1 | D9: 118462943 | E9: 118462943 | F9: 6.14 | G9: 118462943 | H9: 6.14 | I9: 118462943 | J9: 6.14 | K9: 118462943 | M9: Sub Total A2 | O9: 2 | P9: 1210301580 | Q9: 1210301580 | R9: 62.76 | S9: 1210301580 | T9: 62.76 | U9: 1210301580
B10: Provident Funds/ Pension Funds | C10: 1 | D10: 13857087 | E10: 13857087 | F10: 0.72 | G10: 13857087 | H10: 0.72 | I10: 13857087 | J10: 0.72 | K10: 13857087 | M10: A=A1+A2 | O10: 2 | P10: 1210301580 | Q10: 1210301580 | R10: 62.76 | S10: 1210301580 | T10: 62.76 | U10: 1210301580
B11: NBFCs registered with RBI | C11: 9 | D11: 80564 | E11: 80564 | F11: 0 | G11: 80564 | H11: 0 | I11: 80564 | J11: 0 | K11: 80564
B12: Sub Total B1 | C12: 133 | D12: 238980844 | E12: 238980844 | F12: 12.39 | G12: 238980844 | H12: 12.39 | I12: 238980844 | J12: 12.39 | K12: 238933154
B13: B10) Institutions (Foreign) | C13: - | D13: - | E13: - | F13: 0 | G13: - | H13: 0 | I13: - | J13: 0 | K13: - | M13: Share Holding
B14: Foreign Portfolio Investors Category I | C14: 711 | D14: 182572904 | E14: 182572904 | F14: 9.47 | G14: 182572904 | H14: 9.47 | I14: 182572904 | J14: 9.47 | K14: 182572904 | M14: Particulars | N14: 45717 | O14: 45809 | P14: 45901 | Q14: 45992 | R14: 46082
B15: Foreign Portfolio Investors Category II | C15: 36 | D15: 5157589 | E15: 5157589 | F15: 0.27 | G15: 5157589 | H15: 0.27 | I15: 5157589 | J15: 0.27 | K15: 5144309 | M15: Promoters | N15: 0.6276 | O15: 0.6276 | P15: 0.6276 | Q15: 0.6276 | R15: 0.6276
B16: Sub Total B2 | C16: 747 | D16: 187730493 | E16: 187730493 | F16: 9.74 | G16: 187730493 | H16: 9.74 | I16: 187730493 | J16: 9.74 | K16: 187717213 | M16: Nestle S.A. | N16: 34.28 | O16: 34.28 | P16: 34.28 | Q16: 34.28 | R16: 34.28
B17: B14) Central Government/ State Government(s)/ President of India | C17: - | D17: - | E17: - | F17: 0 | G17: - | H17: 0 | I17: - | J17: 0 | K17: - | M17: Maggi Enterprises Ltd | N17: 28.48 | O17: 28.48 | P17: 28.48 | Q17: 28.48 | R17: 28.48
B18: Shareholding by Companies or Bodies Corporate where Central / State Government is a promoter | C18: 3 | D18: 58931 | E18: 58931 | F18: 0 | G18: 58931 | H18: 0 | I18: 58931 | J18: 0 | K18: 58931 | M18: FIIs | N18: 0.1002 | O18: 0.1028 | P18: 0.0982 | Q18: 0.0981 | R18: 0.0974
B19: Sub Total B3 | C19: 3 | D19: 58931 | E19: 58931 | F19: 0 | G19: 58931 | H19: 0 | I19: 58931 | J19: 0 | K19: 58931 | M19: DIIs | N19: 0.113 | O19: 0.1118 | P19: 0.1175 | Q19: 0.121 | R19: 0.124
B20: B17) Non-Institutions | C20: - | D20: - | E20: - | F20: 0 | G20: - | H20: 0 | I20: - | J20: 0 | K20: - | M20: Life Insurance Corporation Of India | N20: 4.67 | O20: 5.25 | P20: 5.71 | Q20: 6.04 | R20: 6.14
B21: Directors and their relatives (excluding independent directors and nominee directors) | C21: 2 | D21: 1156 | E21: 1156 | F21: 0 | G21: 1156 | H21: 0 | I21: 1156 | J21: 0 | K21: 1156 | M21: Sbi Nifty 50 Etf | N21: 1.28
B22: Key Managerial Personnel | C22: 1 | D22: 720 | E22: 720 | F22: 0 | G22: 720 | H22: 0 | I22: 720 | J22: 0 | K22: 720 | M22: Public | N22: 0.159 | O22: 0.1576 | P22: 0.1563 | Q22: 0.1531 | R22: 0.1509
B23: Investor Education and Protection Fund (IEPF) | C23: 1 | D23: 2946648 | E23: 2946648 | F23: 0.15 | G23: 2946648 | H23: 0.15 | I23: 2946648 | J23: 0.15 | K23: 2946648 | M23: No. of Shareholders | N23: 538165 | O23: 519439 | P23: 546818 | Q23: 506673 | R23: 492124
B24: Resident Individuals holding nominal share capital up to Rs. 2 lakhs | C24: 468638 | D24: 156458392 | E24: 156458392 | F24: 8.11 | G24: 156458392 | H24: 8.11 | I24: 156458392 | J24: 8.11 | K24: 155042302
B25: Resident Individuals holding nominal share capital in excess of Rs. 2 lakhs | C25: 92 | D25: 76430533 | E25: 76430533 | F25: 3.96 | G25: 76430533 | H25: 3.96 | I25: 76430533 | J25: 3.96 | K25: 76304633
B26: Non Resident Indians (NRIs) | C26: 14298 | D26: 22339751 | E26: 22339751 | F26: 1.16 | G26: 22339751 | H26: 1.16 | I26: 22339751 | J26: 1.16 | K26: 22325721
B27: Foreign Nationals | C27: 1 | D27: 16200 | E27: 16200 | F27: 0 | G27: 16200 | H27: 0 | I27: 16200 | J27: 0 | K27: 16200
B28: Bodies Corporate | C28: 1665 | D28: 22443870 | E28: 22443870 | F28: 1.16 | G28: 22443870 | H28: 1.16 | I28: 22443870 | J28: 1.16 | K28: 22417760
B29: Any Other (specify) | C29: 6541 | D29: 10605202 | E29: 10605202 | F29: 0.55 | G29: 10605202 | H29: 0.55 | I29: 10605202 | J29: 0.55 | K29: 10605202
B30: Clearing Members | C30: 46 | D30: 2804568 | E30: 2804568 | F30: 0.15 | G30: 2804568 | H30: 0.15 | I30: 2804568 | J30: 0.15 | K30: 2804568
B31: Overseas Corporate Bodies | C31: 1 | D31: 10000 | E31: 10000 | F31: 0 | G31: 10000 | H31: 0 | I31: 10000 | J31: 0 | K31: 10000
B32: Trusts | C32: 59 | D32: 487164 | E32: 487164 | F32: 0.03 | G32: 487164 | H32: 0.03 | I32: 487164 | J32: 0.03 | K32: 487164
B33: Foreign Portfolio Investor (Category - III) | C33: 1 | D33: 4000 | E33: 4000 | F33: 0 | G33: 4000 | H33: 0 | I33: 4000 | J33: 0 | K33: 4000
B34: Unclaimed or Suspense or Escrow Account | C34: 1 | D34: 1693141 | E34: 1693141 | F34: 0.09 | G34: 1693141 | H34: 0.09 | I34: 1693141 | J34: 0.09 | K34: 1693141
B35: HUF | C35: 6265 | D35: 4709675 | E35: 4709675 | F35: 0.24 | G35: 4709675 | H35: 0.24 | I35: 4709675 | J35: 0.24 | K35: 4709675
... B38: B=B1+B2+B3+B4 | C38: 492122 | D38: 718012740 | E38: 718012740 | F38: 37.24 | G38: 718012740 | H38: 37.24 | I38: 718012740 | J38: 37.24 | K38: 716369640

Sheet Consolodated Financials
B1: Income Statement For the year ended 2026 | J1: Balance sheet For the year ended 2026
B2: Particulars | C2: Mar '24 | D2: Mar '25 | E2: Mar '26 | G2: % change | J2: Particulars | K2: Mar '24 | L2: Mar '25 | M2: Mar '26 | O2: % change
B3: Income | G3: Mar '25 | H3: Mar '26 | J3: Sources Of Funds | O3: Mar '25 | P3: Mar '26
B4: Sales Turnover | C4: 24393.89 | D4: 20201.56 | E4: 23154.6 | G4: =(D4-C4)/C4 -> -0.17185984 | H4: =(E4-D4)/D4 -> 0.14617881 | J4: Total Share Capital | K4: 96.42 | L4: 96.42 | M4: 192.83 | O4: =(L4-K4)/K4 -> 0 | P4: =(M4-L4)/L4 -> 0.99989629
B5: Excise Duty | C5: 0 | D5: 0 | E5: 0 | J5: Equity Share Capital | K5: 96.42 | L5: 96.42 | M5: 192.83 | O5: =(L5-K5)/K5 -> 0 | P5: =(M5-L5)/L5 -> 0.99989629
B6: Net Sales | C6: 24393.89 | D6: 20201.56 | E6: 23154.6 | G6: =(D6-C6)/C6 -> -0.17185984 | H6: =(E6-D6)/D6 -> 0.14617881 | J6: Share Application Money | K6: 0 | L6: 0 | M6: 0
B7: Other Income | C7: 152.33 | D7: 242.28 | E7: 161.13 | G7: =(D7-C7)/C7 -> 0.59049432 | H7: =(E7-D7)/D7 -> -0.33494304 | J7: Preference Share Capital | K7: 0 | L7: 0 | M7: 0
B8: Stock Adjustments | C8: 45.68 | D8: 139.66 | E8: 168.23 | G8: =(D8-C8)/C8 -> 2.0573555 | H8: =(E8-D8)/D8 -> 0.20456824 | J8: Init. Contribution Settler | K8: 0 | L8: 0 | M8: 0
B9: Total Income | C9: 24591.9 | D9: 20583.5 | E9: 23483.96 | G9: =(D9-C9)/C9 -> -0.16299676 | H9: =(E9-D9)/D9 -> 0.1409119 | J9: Preference Share Application Money | K9: 0 | L9: 0 | M9: 0
B10: Expenditure | J10: Employee Stock Opiton | K10: 0 | L10: 0 | M10: 0
B11: Raw Materials | C11: 10754.25 | D11: 8889.46 | E11: 10509.52 | G11: =(D11-C11)/C11 -> -0.17340028 | H11: =(E11-D11)/D11 -> 0.18224504 | J11: Reserves | K11: 3244.47 | L11: 3913.79 | M11: 4964.14 | O11: =(L11-K11)/K11 -> 0.20629564 | P11: =(M11-L11)/L11 -> 0.26837158
B12: Power & Fuel Cost | C12: 0 | D12: 0 | E12: 0 | J12: Networth | K12: 3340.89 | L12: 4010.21 | M12: 5156.97 | O12: =(L12-K12)/K12 -> 0.20034183 | P12: =(M12-L12)/L12 -> 0.28596009
B13: Employee Cost | C13: 2336.06 | D13: 2023.71 | E13: 2165.81 | G13: =(D13-C13)/C13 -> -0.13370804 | H13: =(E13-D13)/D13 -> 0.070217571 | J13: Secured Loans | K13: 31.14 | L13: 753.34 | M13: 24.44 | O13: =(L13-K13)/K13 -> 23.192036 | P13: =(M13-L13)/L13 -> -0.96755781
B14: Other Manufacturing Expenses | C14: 0 | D14: 0 | E14: 0 | J14: Unsecured Loans | K14: 0 | L14: 0 | M14: 0
B15: Selling and Admin Expenses | C15: 0 | D15: 0 | E15: 0 | J15: Total Debt | K15: 31.14 | L15: 753.34 | M15: 24.44 | O15: =(L15-K15)/K15 -> 23.192036 | P15: =(M15-L15)/L15 -> -0.96755781
B16: Miscellaneous Expenses | C16: 5529.45 | D16: 4672.1 | E16: 5341.44 | G16: =(D16-C16)/C16 -> -0.15505159 | H16: =(E16-D16)/D16 -> 0.1432632 | J16: Minority Interest | K16: 0 | L16: 0 | M16: 0
B17: Preoperative Exp Capitalised | C17: 0 | D17: 0 | E17: 0 | J17: Policy Holders Funds | K17: 0 | L17: 0 | M17: 0
B18: Total Expenses | C18: 18619.76 | D18: 15585.27 | E18: 18016.77 | G18: =(D18-C18)/C18 -> -0.16297149 | H18: =(E18-D18)/D18 -> 0.1560127 | J18: Group Share in Joint Venture | K18: 0 | L18: 0 | M18: 0
B19: Operating Profit | C19: 5819.81 | D19: 4755.95 | E19: 5306.06 | G19: =(D19-C19)/C19 -> -0.18279978 | H19: =(E19-D19)/D19 -> 0.11566774 | J19: Total Liabilities | K19: 3372.03 | L19: 4763.55 | M19: 5181.41 | O19: =(L19-K19)/K19 -> 0.41266537 | P19: =(M19-L19)/L19 -> 0.087720293
B20: PBDIT | C20: 5972.14 | D20: 4998.23 | E20: 5467.19 | G20: =(D20-C20)/C20 -> -0.16307555 | H20: =(E20-D20)/D20 -> 0.093825214 | K20: Mar '24 | L20: Mar '25 | M20: Mar '26
B21: Interest | C21: 145.49 | D21: 136 | E21: 158.31 | G21: =(D21-C21)/C21 -> -0.065227851 | H21: =(E21-D21)/D21 -> 0.16404412 | J21: Application Of Funds
B22: PBDT | C22: 5826.65 | D22: 4862.23 | E22: 5308.88 | G22: =(D22-C22)/C22 -> -0.16551878 | H22: =(E22-D22)/D22 -> 0.091861142 | J22: Gross Block | K22: 5201.96 | L22: 6646.17 | M22: 6797.4 | O22: =(L22-K22)/K22 -> 0.27762805 | P22: =(M22-L22)/L22 -> 0.022754459
B23: Depreciation | C23: 537.78 | D23: 522.16 | E23: 699.23 | G23: =(D23-C23)/C23 -> -0.029045335 | H23: =(E23-D23)/D23 -> 0.33911062 | J23: Less: Revaluation Reserves | K23: 0 | L23: 0 | M23: 0
B24: Other Written Off | C24: 0 | D24: 0 | E24: 0 | J24: Less: Accum. Depreciation | K24: 0 | L24: 0 | M24: 0
B25: Profit Before Tax | C25: 5288.87 | D25: 4340.07 | E25: 4609.65 | G25: =(D25-C25)/C25 -> -0.1793956 | H25: =(E25-D25)/D25 -> 0.062114206 | J25: Net Block | K25: 5201.96 | L25: 6646.17 | M25: 6797.4 | O25: =(L25-K25)/K25 -> 0.27762805 | P25: =(M25-L25)/L25 -> 0.022754459
B26: Extra-ordinary items | C26: 0 | D26: 0 | E26: 0 | J26: Capital Work in Progress | K26: 0 | L26: 0 | M26: 0
B27: PBT (Post Extra-ord Items) | C27: 5288.87 | D27: 4340.07 | E27: 4609.65 | G27: =(D27-C27)/C27 -> -0.1793956 | H27: =(E27-D27)/D27 -> 0.062114206 | J27: Investments | K27: 463.87 | L27: 575.03 | M27: 530.92 | O27: =(L27-K27)/K27 -> 0.2396361 | P27: =(M27-L27)/L27 -> -0.076709041
B28: Tax | C28: 1356.03 | D28: 1108.53 | E28: 1065.05 | G28: =(D28-C28)/C28 -> -0.18251809 | H28: =(E28-D28)/D28 -> -0.039223115 | J28: Inventories | K28: 2089.36 | L28: 2850.14 | M28: 2569.22 | O28: =(L28-K28)/K28 -> 0.36412107 | P28: =(M28-L28)/L28 -> -0.098563579
B29: Reported Net Profit | C29: 3932.84 | D29: 3231.54 | E29: 3544.6 | G29: =(D29-C29)/C29 -> -0.17831898 | H29: =(E29-D29)/D29 -> 0.096876412 | J29: Sundry Debtors | K29: 300.46 | L29: 363.15 | M29: 329.47 | O29: =(L29-K29)/K29 -> 0.20864674 | P29: =(M29-L29)/L29 -> -0.092744045
B30: Minority Interest | C30: 0 | D30: 0 | E30: 0 | J30: Cash and Bank Balance | K30: 778.85 | L30: 95.65 | M30: 1340.87 | O30: =(L30-K30)/K30 -> -0.87719073 | P30: =(M30-L30)/L30 -> 13.018505
B31: Share Of P/L Of Associates | C31: 0 | D31: 23.95 | E31: 45.52 | H31: =(E31-D31)/D31 -> 0.9006263 | J31: Total Current Assets | K31: 3168.67 | L31: 3308.94 | M31: 4239.56 | O31: =(L31-K31)/K31 -> 0.044267784 | P31: =(M31-L31)/L31 -> 0.28124414
B32: Net P/L After Minority Interest & Share Of Associates | C32: 3928.47 | D32: 3024.17 | E32: 3378.3 | G32: =(D32-C32)/C32 -> -0.2301914 | H32: =(E32-D32)/D32 -> 0.1170999 | J32: Loans and Advances | K32: 1688.56 | L32: 1663.18 | M32: 1614.62 | O32: =(L32-K32)/K32 -> -0.015030559 | P32: =(M32-L32)/L32 -> -0.02919708
B33: Total Value Addition | C33: 7865.51 | D33: 6695.81 | E33: 7507.25 | G33: =(D33-C33)/C33 -> -0.14871254 | H33: =(E33-D33)/D33 -> 0.12118623 | J33: Fixed Deposits | K33: 0 | L33: 0 | M33: 0
B34: Preference Dividend | C34: 0 | D34: 0 | E34: 0 | J34: Total CA, Loans & Advances | K34: 4857.23 | L34: 4972.12 | M34: 5854.18 | O34: =(L34-K34)/K34 -> 0.023653399 | P34: =(M34-L34)/L34 -> 0.17740119
B35: Equity Dividend | C35: 0 | D35: 0 | E35: 0 | J35: Deferred Credit | K35: 0 | L35: 0 | M35: 0
B36: Corporate Dividend Tax | C36: 0 | D36: 0 | E36: 0 | J36: Current Liabilities | K36: 3972.21 | L36: 4097.34 | M36: 4869.68 | O36: =(L36-K36)/K36 -> 0.031501356 | P36: =(M36-L36)/L36 -> 0.1884979
B37: Per share data (annualised) | J37: Provisions | K37: 3178.82 | L37: 3332.43 | M37: 3131.4 | O37: =(L37-K37)/K37 -> 0.048322963 | P37: =(M37-L37)/L37 -> -0.060325348
B38: Shares in issue (lakhs) | C38: 9642 | D38: 9642 | E38: 19283 | G38: =(D38-C38)/C38 -> 0 | H38: =(E38-D38)/D38 -> 0.99989629 | J38: Total CL & Provisions | K38: 7151.03 | L38: 7429.77 | M38: 8001.08 | O38: =(L38-K38)/K38 -> 0.038979 | P38: =(M38-L38)/L38 -> 0.076894709
B39: Earning Per Share (Rs) | C39: 40.79 | D39: 33.52 | E39: 18.38 | G39: =(D39-C39)/C39 -> -0.17822996 | H39: =(E39-D39)/D39 -> -0.45167064 | J39: Net Current Assets | K39: -2293.8 | L39: -2457.65 | M39: -2146.9 | O39: =(L39-K39)/K39 -> 0.071431685 | P39: =(M39-L39)/L39 -> -0.12644193
B40: Equity Dividend (%) | C40: 0 | D40: 0 | E40: 0 | J40: Minority Interest | K40: 0 | L40: 0 | M40: 0
...

Sheet Peers
B1: Peer Evaluation
B3: NESTLEIND | C3: Nestle India Limited is a subsidiary of Nestle which is a Swiss MNC. The company operates in the Food segment.Nestle India a subsidiary of Nestle S A (holds 62% stake) is primarily involved in the Food business which incorporates product groups viz. Milk Products and Nutrition, Prepared dishes and Cooking aids, Powdered and Liquid Beverages and Confectionery. It owns brands such as NESCAFÉ, MAGGI, MILKYBAR, KIT KAT, BAR-ONE, MILKMAID, NESTEA etc
B6: BRITANNIA | C6: Britannia Industries is one of India's leading food companies with a 100-year legacy and annual revenues in excess of Rs. 16000 Cr. Britannia is among the most trusted food brands, and manufactures Indias favorite brands like Good Day, Tiger, NutriChoice, Milk Bikis and Marie Gold, which are household names in India. Britannia's product portfolio includes Biscuits, Bread, Cakes, Rusk, and Dairy products, including Cheese, Beverages, Milk and Yoghurt
B9: BIKAJI | C9: Bikaji Foods International Limited is one of India's largest fast-moving consumer goods ("FMCG") brands. The company's product range includes six principal categories: bhujia, namkeen, packaged sweets, papad, western snacks as well as other snacks which primarily include gift packs (assortment), frozen food, mathri range, and cookies.
B12: Mrs. BECTORFOOD | C12: Mrs. Bectors Food Specialities Ltd is a leading Indian manufacturer of biscuits, bakery products, and ready-to-eat desserts. It operates through two major brands Cremica (biscuits, cookies, crackers, creams) and English Oven (breads, bakery, value-added products). The company is also a preferred supplier to top QSR chains like McDonald’s, Domino’s, KFC, and Subway in India.
B15: Attribute | C15: LTP (₹) | D15: Change (%) | E15: Sales (₹ crore) | F15: PAT (₹ crore) | G15: Equity (₹ crore) | H15: Operating Profit Margin (OPM%) | I15: Net Profit Margin (NPM%) | J15: Earnings Per Share (EPS) | K15: Cash Earnings Per Share (CEPS)
B16: NESTLEIND | C16: 1430.3 | D16: -2.01 | E16: 23154.6 | F16: 3544.6 | G16: 192.83 | H16: 23.61 | I16: 15.31 | J16: 18.38 | K16: 22.01
B17: BRITANNIA | C17: 5405 | D17: 0.63 | E17: 18445.82 | F17: 2561.72 | G17: 24.09 | H17: 20.11 | I17: 13.89 | J17: 106.35 | K17: 119.01
B18: BIKAJI | C18: 669.7 | D18: 3.11 | E18: 2536.86 | F18: 212.42 | G18: 25.06 | H18: 14.44 | I18: 8.37 | J18: 8.48 | K18: 11.24
B19: BECTORFOOD | C19: 181.95 | D19: 0.64 | E19: 1741.91 | F19: 121.03 | G19: 61.35 | H19: 14.11 | I19: 6.95 | J19: 20.1 | K19: 31.34
B21: Nestle | H21: BRITANNIA
B22: Particulars | C22: 45536 | D22: 45901 | E22: 45717 | F22: 46082 | H22: Particulars | I22: 44621 | J22: 44986 | K22: 45352 | L22: 45717 | M22: 46082
B23: Debtor Days | C23: 4 | D23: 4 | E23: 7 | F23: 5 | H23: Debtor Days | I23: 9 | J23: 7 | K23: 9 | L23: 9 | M23: 9
B24: Inventory Days | C24: 83 | D24: 83 | E24: 139 | F24: 91 | H24: Inventory Days | I24: 57 | J24: 45 | K24: 45 | L24: 43 | M24: 44
B25: Days Payable | C25: 92 | D25: 112 | E25: 128 | F25: 112 | H25: Days Payable | I25: 55 | J25: 55 | K25: 63 | L25: 60 | M25: 62
B26: Cash Conversion Cycle | C26: -5 | D26: -24 | E26: 18 | F26: -16 | H26: Cash Conversion Cycle | I26: 10 | J26: -2 | K26: -9 | L26: -9 | M26: -9
B27: Working Capital Days | C27: -10 | D27: -19 | E27: -19 | F27: -24 | H27: Working Capital Days | I27: -31 | J27: -31 | K27: -30 | L27: -23 | M27: 3
B28: ROCE % | C28: 1.53 | D28: 1.69 | E28: 0.96 | F28: 0.84 | H28: ROCE % | I28: 0.41 | J28: 0.49 | K28: 0.49 | L28: 0.53 | M28: 0.56
B30: BIKAJI | H30: BECTORFOOD
B31: Particulars | C31: 44621 | D31: 44986 | E31: 45352 | F31: 45717 | H31: Particulars | I31: 44256 | J31: 44621 | K31: 44986 | L31: 45352 | M31: 45717
B32: Debtor Days | C32: 17 | D32: 15 | E32: 16 | F32: 14 | H32: Debtor Days | I32: 29 | J32: 28 | K32: 25 | L32: 31 | M32: 27
B33: Inventory Days | C33: 27 | D33: 21 | E33: 20 | F33: 22 | H33: Inventory Days | I33: 46 | J33: 54 | K33: 41 | L33: 46 | M33: 52
B34: Days Payable | C34: 16 | D34: 14 | E34: 14 | F34: 14 | H34: Days Payable | I34: 46 | J34: 38 | K34: 38 | L34: 45 | M34: 38
B35: Cash Conversion Cycle | C35: 28 | D35: 21 | E35: 22 | F35: 22 | H35: Cash Conversion Cycle | I35: 30 | J35: 44 | K35: 28 | L35: 31 | M35: 42
B36: Working Capital Days | C36: 14 | D36: 19 | E36: 16 | F36: 28 | H36: Working Capital Days | I36: 23 | J36: 20 | K36: 13 | L36: 9 | M36: 18
B37: ROCE % | C37: 0.13 | D37: 0.18 | E37: 0.29 | F37: 0.18 | H37: ROCE % | I37: 0.2 | J37: 0.13 | K37: 0.19 | L37: 0.24 | M37: 0.16

Sheet Standalone Financials
B1: Income Statement For the year ended 2026 | P1: Balance sheet For the year ended 2026
B2: Particulars | C2: Dec '21 | D2: Dec '22 | E2: Dec '23 | F2: Mar '24 | G2: Mar '25 | H2: Mar '26 | J2: % Change | P2: Particulars | Q2: Dec '21 | R2: Dec '22 | S2: Dec '23 | T2: Mar '24 | U2: Mar '25 | V2: Mar '26 | X2: % Change
B3: Income | J3: Dec '22 | K3: Dec '23 | L3: Mar '24 | M3: Mar '25 | N3: Mar '26 | P3: Equity Capital | Q3: 96 | R3: 96 | S3: 96 | T3: 96 | U3: 96 | V3: 193 | X3: Dec '22 | Y3: Dec '23 | Z3: Mar '24 | AA3: Mar '25 | AB3: Mar '26
B4: Sales Turnover | C4: 14709.41 | D4: 16896.96 | E4: 19126.3 | F4: 24393.89 | G4: 20201.56 | H4: 23154.6 | J4: =(D4-C4)/C4 -> 0.14871773 | K4: =(E4-D4)/D4 -> 0.13193734 | L4: =(F4-E4)/E4 -> 0.27541082 | M4: =(G4-F4)/F4 -> -0.17185984 | N4: =(H4-G4)/G4 -> 0.14617881 | P4: Reserves | Q4: 1850 | R4: 2363 | S4: 2363 | T4: 3244 | U4: 4021 | V4: 5116 | X4: =(R4-Q4)/Q4 -> 0.2772973 | Y4: =(S4-R4)/R4 -> 0 | Z4: =(T4-S4)/S4 -> 0.37283115 | AA4: =(U4-T4)/T4 -> 0.23951911 | AB4: =(V4-U4)/U4 -> 0.27232032
B5: Net Sales | C5: 14709.41 | D5: 16896.96 | E5: 19126.3 | F5: 24393.89 | G5: 20201.56 | H5: 23154.6 | J5: =(D5-C5)/C5 -> 0.14871773 | K5: =(E5-D5)/D5 -> 0.13193734 | L5: =(F5-E5)/E5 -> 0.27541082 | M5: =(G5-F5)/F5 -> -0.17185984 | N5: =(H5-G5)/G5 -> 0.14617881 | P5: Borrowings | Q5: 266 | R5: 271 | S5: 271 | T5: 345 | U5: 1167 | V5: 444 | X5: =(R5-Q5)/Q5 -> 0.018796992 | Y5: =(S5-R5)/R5 -> 0 | Z5: =(T5-S5)/S5 -> 0.27306273 | AA5: =(U5-T5)/T5 -> 2.3826087 | AB5: =(V5-U5)/U5 -> -0.61953728
B6: Other Income | C6: -267.95 | D6: 214.92 | E6: 115.5 | F6: 109.43 | G6: 269.11 | H6: 161.13 | J6: =(D6-C6)/C6 -> -1.8020899 | K6: =(E6-D6)/D6 -> -0.46259073 | L6: =(F6-E6)/E6 -> -0.052554113 | M6: =(G6-F6)/F6 -> 1.4591977 | N6: =(H6-G6)/G6 -> -0.40124856 | P6: Long term Borrowings | Q6: 27 | R6: 27 | S6: 27 | T6: 25 | U6: 22 | V6: 20 | X6: =(R6-Q6)/Q6 -> 0 | Y6: =(S6-R6)/R6 -> 0 | Z6: =(T6-S6)/S6 -> -0.074074074 | AA6: =(U6-T6)/T6 -> -0.12 | AB6: =(V6-U6)/U6 -> -0.090909091
B7: Stock Adjustments | C7: 62.7 | D7: 250.27 | E7: 40.01 | F7: 45.68 | G7: 139.66 | H7: 168.23 | J7: =(D7-C7)/C7 -> 2.991547 | K7: =(E7-D7)/D7 -> -0.84013266 | L7: =(F7-E7)/E7 -> 0.14171457 | M7: =(G7-F7)/F7 -> 2.0573555 | N7: =(H7-G7)/G7 -> 0.20456824 | P7: Short term Borrowings | Q7: 7 | R7: 3 | S7: 3 | T7: 6 | U7: 731 | V7: 4 | X7: =(R7-Q7)/Q7 -> -0.57142857 | Y7: =(S7-R7)/R7 -> 0 | Z7: =(T7-S7)/S7 -> 1 | AA7: =(U7-T7)/T7 -> 120.83333 | AB7: =(V7-U7)/U7 -> -0.99452804
B8: Total Income | C8: 14504.16 | D8: 17362.15 | E8: 19281.81 | F8: 24549 | G8: 20610.33 | H8: 23483.96 | J8: =(D8-C8)/C8 -> 0.19704623 | K8: =(E8-D8)/D8 -> 0.1105658 | L8: =(F8-E8)/E8 -> 0.27316886 | M8: =(G8-F8)/F8 -> -0.16044116 | N8: =(H8-G8)/G8 -> 0.13942669 | P8: Lease Liabilities | Q8: 232 | R8: 240 | S8: 240 | T8: 313 | U8: 414 | V8: 420 | X8: =(R8-Q8)/Q8 -> 0.034482759 | Y8: =(S8-R8)/R8 -> 0 | Z8: =(T8-S8)/S8 -> 0.30416667 | AA8: =(U8-T8)/T8 -> 0.32268371 | AB8: =(V8-U8)/U8 -> 0.014492754
B9: Expenditure | P9: Other Liabilities | Q9: 6021 | R9: 6249 | S9: 6249 | T9: 6838 | U9: 7040 | V9: 7604 | X9: =(R9-Q9)/Q9 -> 0.037867464 | Y9: =(S9-R9)/R9 -> 0 | Z9: =(T9-S9)/S9 -> 0.094255081 | AA9: =(U9-T9)/T9 -> 0.029540801 | AB9: =(V9-U9)/U9 -> 0.080113636
B10: Raw Materials | C10: 6443.79 | D10: 8073.54 | E10: 8472.72 | F10: 10846.5 | G10: 8971.67 | H10: 10509.52 | J10: =(D10-C10)/C10 -> 0.25291793 | K10: =(E10-D10)/D10 -> 0.049442995 | L10: =(F10-E10)/E10 -> 0.28016741 | M10: =(G10-F10)/F10 -> -0.17285115 | N10: =(H10-G10)/G10 -> 0.17141179 | P10: Trade Payables | Q10: 1748 | R10: 2121 | S10: 2121 | T10: 2812 | U10: 2624 | V10: 3160 | X10: =(R10-Q10)/Q10 -> 0.21338673 | Y10: =(S10-R10)/R10 -> 0 | Z10: =(T10-S10)/S10 -> 0.32578972 | AA10: =(U10-T10)/T10 -> -0.06685633 | AB10: =(V10-U10)/U10 -> 0.20426829
B11: Power & Fuel Cost | C11: 408.66 | D11: 572.61 | E11: 0 | F11: 674.83 | G11: 536.65 | H11: 0 | J11: =(D11-C11)/C11 -> 0.40118925 | K11: =(E11-D11)/D11 -> -1 | M11: =(G11-F11)/F11 -> -0.20476268 | N11: =(H11-G11)/G11 -> -1 | P11: Advance from Customers | Q11: 69 | R11: 114 | T11: 16 | U11: 27
B12: Employee Cost | C12: 1521.3 | D12: 1635.46 | E12: 1849.18 | F12: 2336.06 | G12: 2023.71 | H12: 2165.81 | J12: =(D12-C12)/C12 -> 0.075041083 | K12: =(E12-D12)/D12 -> 0.13067883 | L12: =(F12-E12)/E12 -> 0.26329508 | M12: =(G12-F12)/F12 -> -0.13370804 | N12: =(H12-G12)/G12 -> 0.070217571 | P12: Other liability items | Q12: 4204 | R12: 4014 | S12: 4128 | T12: 4010 | U12: 4389 | V12: 4444 | X12: =(R12-Q12)/Q12 -> -0.045195052 | Y12: =(S12-R12)/R12 -> 0.028400598 | Z12: =(T12-S12)/S12 -> -0.028585271 | AA12: =(U12-T12)/T12 -> 0.094513716 | AB12: =(V12-U12)/U12 -> 0.012531328
B13: Selling and Admin Expenses | C13: 764.4 | D13: 695.59 | E13: 39.5 | F13: 1287.68 | G13: 965.86 | H13: 0 | J13: =(D13-C13)/C13 -> -0.090018315 | K13: =(E13-D13)/D13 -> -0.94321367 | L13: =(F13-E13)/E13 -> 31.599494 | M13: =(G13-F13)/F13 -> -0.24992234 | N13: =(H13-G13)/G13 -> -1 | P13: Total Liabilities | Q13: 8234 | R13: 8979 | S13: 8979 | T13: 10523 | U13: 12324 | V13: 13357 | X13: =(R13-Q13)/Q13 -> 0.090478504 | Y13: =(S13-R13)/R13 -> 0 | AA13: =(U13-T13)/T13 -> 0.17114891 | AB13: =(V13-U13)/U13 -> 0.083820188
B14: Miscellaneous Expenses | C14: 2042.42 | D14: 2457.48 | E14: 4333.92 | F14: 3474.69 | G14: 3091.37 | H14: 5341.44 | J14: =(D14-C14)/C14 -> 0.20321971 | K14: =(E14-D14)/D14 -> 0.76356267 | L14: =(F14-E14)/E14 -> -0.19825701 | M14: =(G14-F14)/F14 -> -0.11031775 | N14: =(H14-G14)/G14 -> 0.72785529 | P14: Fixed Assets | Q14: 2995 | R14: 3044 | S14: 3044 | T14: 3460 | U14: 5474 | V14: 6290 | X14: =(R14-Q14)/Q14 -> 0.016360601 | Y14: =(S14-R14)/R14 -> 0 | Z14: =(T14-S14)/S14 -> 0.13666229 | AA14: =(U14-T14)/T14 -> 0.58208092 | AB14: =(V14-U14)/U14 -> 0.14906832
B15: Total Expenses | C15: 11180.57 | D15: 13434.68 | E15: 14695.32 | F15: 18619.76 | G15: 15589.26 | H15: 18016.77 | J15: =(D15-C15)/C15 -> 0.20160958 | K15: =(E15-D15)/D15 -> 0.093834762 | L15: =(F15-E15)/E15 -> 0.26705373 | M15: =(G15-F15)/F15 -> -0.1627572 | N15: =(H15-G15)/G15 -> 0.15571682 | P15: Land | Q15: 141.57 | R15: 141.57 | T15: 150.81 | U15: 215.27 | X15: =(R15-Q15)/Q15 -> 0 | Y15: =(S15-R15)/R15 -> -1 | AA15: =(U15-T15)/T15 -> 0.42742524 | AB15: =(V15-U15)/U15 -> -1
B16: Operating Profit | C16: 3591.54 | D16: 3712.55 | E16: 4470.99 | F16: 5819.81 | G16: 4751.96 | H16: 5306.06 | J16: =(D16-C16)/C16 -> 0.033693068 | K16: =(E16-D16)/D16 -> 0.20429085 | L16: =(F16-E16)/E16 -> 0.30168263 | M16: =(G16-F16)/F16 -> -0.18348537 | N16: =(H16-G16)/G16 -> 0.11660452 | P16: Building | Q16: 1485.32 | R16: 1532.2 | T16: 1820.81 | U16: 2332.31 | X16: =(R16-Q16)/Q16 -> 0.031562222 | Y16: =(S16-R16)/R16 -> -1 | AA16: =(U16-T16)/T16 -> 0.28091893 | AB16: =(V16-U16)/U16 -> -1
B17: PBDIT | C17: 3323.59 | D17: 3927.47 | E17: 4586.49 | F17: 5929.24 | G17: 5021.07 | H17: 5467.19 | J17: =(D17-C17)/C17 -> 0.18169509 | K17: =(E17-D17)/D17 -> 0.16779759 | L17: =(F17-E17)/E17 -> 0.292762 | M17: =(G17-F17)/F17 -> -0.15316803 | N17: =(H17-G17)/G17 -> 0.088849588 | P17: Plant Machinery | Q17: 3286.91 | R17: 3545.66 | T17: 4068.09 | U17: 5931.88 | X17: =(R17-Q17)/Q17 -> 0.078721352 | Y17: =(S17-R17)/R17 -> -1 | AA17: =(U17-T17)/T17 -> 0.45814866 | AB17: =(V17-U17)/U17 -> -1
B18: Interest | C18: 201.19 | D18: 154.57 | E18: 119.29 | F18: 145.49 | G18: 136 | H18: 158.31 | J18: =(D18-C18)/C18 -> -0.23172126 | K18: =(E18-D18)/D18 -> -0.2282461 | L18: =(F18-E18)/E18 -> 0.21963283 | M18: =(G18-F18)/F18 -> -0.065227851 | N18: =(H18-G18)/G18 -> 0.16404412 | P18: Equipments | Q18: 23.08 | R18: 43.23 | T18: 50.93 | U18: 52.3 | X18: =(R18-Q18)/Q18 -> 0.87305026 | Y18: =(S18-R18)/R18 -> -1 | AA18: =(U18-T18)/T18 -> 0.026899666 | AB18: =(V18-U18)/U18 -> -1
B19: PBDT | C19: 3122.4 | D19: 3772.9 | E19: 4467.2 | F19: 5783.75 | G19: 4885.07 | H19: 5308.88 | J19: =(D19-C19)/C19 -> 0.20833333 | K19: =(E19-D19)/D19 -> 0.1840229 | L19: =(F19-E19)/E19 -> 0.29471481 | M19: =(G19-F19)/F19 -> -0.15538016 | N19: =(H19-G19)/G19 -> 0.086756177 | P19: Computers | Q19: 97.64 | R19: 129.24 | T19: 155.25 | U19: 167.69 | X19: =(R19-Q19)/Q19 -> 0.32363785 | Y19: =(S19-R19)/R19 -> -1 | AA19: =(U19-T19)/T19 -> 0.080128824 | AB19: =(V19-U19)/U19 -> -1
B20: Depreciation | C20: 390.19 | D20: 403.01 | E20: 428.91 | F20: 537.78 | G20: 518.17 | H20: 699.23 | J20: =(D20-C20)/C20 -> 0.032855788 | K20: =(E20-D20)/D20 -> 0.064266395 | L20: =(F20-E20)/E20 -> 0.25382947 | M20: =(G20-F20)/F20 -> -0.036464725 | N20: =(H20-G20)/G20 -> 0.349422 | P20: Furniture n fittings | Q20: 65.14 | R20: 64.41 | T20: 67.67 | U20: 71.23 | X20: =(R20-Q20)/Q20 -> -0.011206632 | Y20: =(S20-R20)/R20 -> -1 | AA20: =(U20-T20)/T20 -> 0.052608246 | AB20: =(V20-U20)/U20 -> -1
B21: Profit Before Tax | C21: 2732.21 | D21: 3369.89 | E21: 4038.29 | F21: 5245.97 | G21: 4366.9 | H21: 4609.65 | J21: =(D21-C21)/C21 -> 0.23339348 | K21: =(E21-D21)/D21 -> 0.19834475 | L21: =(F21-E21)/E21 -> 0.29905727 | M21: =(G21-F21)/F21 -> -0.16757054 | N21: =(H21-G21)/G21 -> 0.055588633 | P21: Railway sidings | Q21: 0 | R21: 0 | T21: 0 | U21: 0
B22: PBT (Post Extra-ord Items) | C22: 2732.21 | D22: 3369.89 | E22: 4038.29 | F22: 5245.97 | G22: 4366.9 | H22: 4609.65 | J22: =(D22-C22)/C22 -> 0.23339348 | K22: =(E22-D22)/D22 -> 0.19834475 | L22: =(F22-E22)/E22 -> 0.29905727 | M22: =(G22-F22)/F22 -> -0.16757054 | N22: =(H22-G22)/G22 -> 0.055588633 | P22: Vehicles | Q22: 19.08 | R22: 17.69 | T22: 20.12 | U22: 25.34 | X22: =(R22-Q22)/Q22 -> -0.072851153 | Y22: =(S22-R22)/R22 -> -1 | AA22: =(U22-T22)/T22 -> 0.25944334 | AB22: =(V22-U22)/U22 -> -1
B23: Tax | C23: 738.91 | D23: 865.45 | E23: 1039.62 | F23: 1356.03 | G23: 1132.97 | H23: 1065.05 | J23: =(D23-C23)/C23 -> 0.17125225 | K23: =(E23-D23)/D23 -> 0.20124791 | L23: =(F23-E23)/E23 -> 0.30435159 | M23: =(G23-F23)/F23 -> -0.16449489 | N23: =(H23-G23)/G23 -> -0.059948631 | P23: Intangible Assets | Q23: 0 | R23: 0 | S23: 0 | T23: 0 | U23: 0 | V23: 0
B24: Reported Net Profit | C24: 2144.86 | D24: 2390.52 | E24: 2998.67 | F24: 3932.84 | G24: 3314.5 | H24: 3544.6 | J24: =(D24-C24)/C24 -> 0.11453428 | K24: =(E24-D24)/D24 -> 0.25440072 | L24: =(F24-E24)/E24 -> 0.31152811 | M24: =(G24-F24)/F24 -> -0.1572248 | N24: =(H24-G24)/G24 -> 0.069422236 | P24: Other fixed assets | Q24: 0 | R24: 0 | T24: 0 | U24: 0
B25: Total Value Addition | C25: 4736.78 | D25: 5361.14 | E25: 6222.6 | F25: 7773.26 | G25: 6617.59 | H25: 7507.25 | J25: =(D25-C25)/C25 -> 0.13181106 | K25: =(E25-D25)/D25 -> 0.16068597 | L25: =(F25-E25)/E25 -> 0.24919808 | M25: =(G25-F25)/F25 -> -0.1486725 | N25: =(H25-G25)/G25 -> 0.13443867 | P25: Gross Block | Q25: 5118.74 | R25: 5474 | T25: 6333.68 | U25: 8796.02 | X25: =(R25-Q25)/Q25 -> 0.069403799 | Y25: =(S25-R25)/R25 -> -1 | AA25: =(U25-T25)/T25 -> 0.38876925 | AB25: =(V25-U25)/U25 -> -1
B26: Equity Dividend | C26: 1928.31 | D26: 2024.73 | E26: 0 | F26: 3008.18 | G26: 2458.6 | H26: 0 | J26: =(D26-C26)/C26 -> 0.050002334 | K26: =(E26-D26)/D26 -> -1 | M26: =(G26-F26)/F26 -> -0.18269518 | N26: =(H26-G26)/G26 -> -1 | P26: Accumulated Depreciation | Q26: 2124.07 | R26: 2430.3 | T26: 2873.43 | U26: 3322.41 | X26: =(R26-Q26)/Q26 -> 0.14417133 | Y26: =(S26-R26)/R26 -> -1 | AA26: =(U26-T26)/T26 -> 0.15625228 | AB26: =(V26-U26)/U26 -> -1
B27: Per share data (annualised) | P27: CWIP | Q27: 246 | R27: 358 | S27: 358 | T27: 1742 | U27: 1173 | V27: 507 | X27: =(R27-Q27)/Q27 -> 0.45528455 | Y27: =(S27-R27)/R27 -> 0 | Z27: =(T27-S27)/S27 -> 3.8659218 | AA27: =(U27-T27)/T27 -> -0.32663605 | AB27: =(V27-U27)/U27 -> -0.56777494
B28: Shares in issue (lakhs) | C28: 964.16 | D28: 964.16 | E28: 964.2 | F28: 9641.57 | G28: 9641.57 | H28: 19283 | J28: =(D28-C28)/C28 -> 0 | K28: =(E28-D28)/D28 -> 4.148689e-05 | L28: =(F28-E28)/E28 -> 8.999554 | M28: =(G28-F28)/F28 -> 0 | N28: =(H28-G28)/G28 -> 0.99998548 | P28: Investments | Q28: 774 | R28: 778 | S28: 778 | T28: 464 | U28: 706 | V28: 706 | X28: =(R28-Q28)/Q28 -> 0.0051679587 | Y28: =(S28-R28)/R28 -> 0 | Z28: 0 | AA28: =(U28-T28)/T28 -> 0.52155172 | AB28: =(V28-U28)/U28 -> 0
B29: Earning Per Share (Rs) | C29: 222.46 | D29: 247.94 | E29: 311 | F29: 40.79 | G29: 34.38 | H29: 18.38 | J29: =(D29-C29)/C29 -> 0.11453744 | K29: =(E29-D29)/D29 -> 0.25433573 | L29: =(F29-E29)/E29 -> -0.86884244 | M29: =(G29-F29)/F29 -> -0.15714636 | N29: =(H29-G29)/G29 -> -0.46538685 | P29: Other Assets - | Q29: 4219 | R29: 4799 | S29: 4799 | T29: 4857 | U29: 4972 | V29: 5854 | X29: =(R29-Q29)/Q29 -> 0.13747333 | Y29: =(S29-R29)/R29 -> 0 | Z29: =(T29-S29)/S29 -> 0.012085851 | AA29: =(U29-T29)/T29 -> 0.023677167 | AB29: =(V29-U29)/U29 -> 0.1773934
B30: Equity Dividend (%) | C30: 2000 | D30: 2200 | E30: 1670 | F30: 3220 | G30: 2700 | H30: 1200 | J30: =(D30-C30)/C30 -> 0.1 | K30: =(E30-D30)/D30 -> -0.24090909 | L30: =(F30-E30)/E30 -> 0.92814371 | M30: =(G30-F30)/F30 -> -0.16149068 | N30: =(H30-G30)/G30 -> -0.55555556 | P30: Inventories | Q30: 1593 | R30: 1929 | S30: 1929 | T30: 2089 | U30: 2850 | V30: 2569 | X30: =(R30-Q30)/Q30 -> 0.21092279 | Y30: =(S30-R30)/R30 -> 0 | Z30: =(T30-S30)/S30 -> 0.082944531 | AA30: =(U30-T30)/T30 -> 0.36428913 | AB30: =(V30-U30)/U30 -> -0.098596491
B31: Book Value (Rs) | C31: 216.2 | D31: 255.06 | E31: 320.76 | F31: 34.65 | G31: 42.7 | H31: 27.53 | J31: =(D31-C31)/C31 -> 0.17974098 | K31: =(E31-D31)/D31 -> 0.25758645 | L31: =(F31-E31)/E31 -> -0.89197531 | M31: =(G31-F31)/F31 -> 0.23232323 | N31: =(H31-G31)/G31 -> -0.35526932 | P31: Trade receivables | Q31: 166 | R31: 192 | S31: 192 | T31: 300 | U31: 363 | V31: 329 | X31: =(R31-Q31)/Q31 -> 0.15662651 | Y31: =(S31-R31)/R31 -> 0 | Z31: =(T31-S31)/S31 -> 0.5625 | AA31: =(U31-T31)/T31 -> 0.21 | AB31: =(V31-U31)/U31 -> -0.093663912
P32: Cash Equivalents | Q32: 735 | R32: 946 | S32: 946 | T32: 779 | U32: 96 | V32: 1341 | X32: =(R32-Q32)/Q32 -> 0.28707483 | Y32: =(S32-R32)/R32 -> 0 | Z32: =(T32-S32)/S32 -> -0.17653277 | AA32: =(U32-T32)/T32 -> -0.87676508 | AB32: =(V32-U32)/U32 -> 12.96875
P33: Loans n Advances | Q33: 93 | R33: 68 | S33: 66 | T33: 76 | U33: 81 | V33: 80 | X33: =(R33-Q33)/Q33 -> -0.2688172 | Y33: =(S33-R33)/R33 -> -0.029411765 | Z33: =(T33-S33)/S33 -> 0.15151515 | AA33: =(U33-T33)/T33 -> 0.065789474 | AB33: =(V33-U33)/U33 -> -0.012345679
P34: Other asset items | Q34: 1632 | R34: 1665 | S34: 1667 | T34: 1613 | U34: 1582 | V34: 1535 | X34: =(R34-Q34)/Q34 -> 0.020220588 | Y34: =(S34-R34)/R34 -> 0.0012012012 | Z34: =(T34-S34)/S34 -> -0.032393521 | AA34: =(U34-T34)/T34 -> -0.019218847 | AB34: =(V34-U34)/U34 -> -0.029709229
P35: Total Assets | Q35: 8234 | R35: 8979 | S35: 8979 | T35: 10523 | U35: 12324 | V35: 13357 | X35: =(R35-Q35)/Q35 -> 0.090478504 | Y35: =(S35-R35)/R35 -> 0 | Z35: =(T35-S35)/S35 -> 0.17195679 | AA35: =(U35-T35)/T35 -> 0.17114891 | AB35: =(V35-U35)/U35 -> 0.083820188

Sheet Beta
A2: Nestle | E2: Nifty | I2: Beta Calculation
A3: Date | B3: Close | C3: Return | E3: Date | F3: Close | G3: Return
A4: 43922 | B4: 731.49 | E4: 43922 | F4: 8253.7998 | I4: Srl. No. | J4: Particular | K4: Value | L4: Formula
A5: 43924 | B5: 705.8 | C5: =(B5-B4)/B4 -> -0.035120097 | E5: 43924 | F5: 8083.7998 | G5: =(F5-F4)/F4 -> -0.020596574 | I5: 1 | J5: Beta | K5: =SLOPE(C4:C1485,G4:G1485) -> 0.49579971 | L5: =+_xlfn.FORMULATEXT(K5) -> =SLOPE(C4:C1485,G4:G1485)
A6: 43928 | B6: 796.17 | C6: =(B6-B5)/B5 -> 0.1280391 | E6: 43928 | F6: 8792.2002 | G6: =(F6-F5)/F5 -> 0.087632105
A7: 43929 | B7: 788.34 | C7: =(B7-B6)/B6 -> -0.0098345831 | E7: 43929 | F7: 8748.75 | G7: =(F7-F6)/F6 -> -0.0049419024 | I7: 2 | J7: Beta | K7: =_xlfn.COVARIANCE.S(C5:C1485,G5:G1485)/_xlfn.VAR.S(G5:G1485) -> 0.49579971 | L7: =+_xlfn.FORMULATEXT(K7) -> =COVARIANCE.S(C5:C1485,G5:G1485)/VAR.S(G5:G1485)
A8: 43930 | B8: 786.87 | C8: =(B8-B7)/B7 -> -0.0018646777 | E8: 43930 | F8: 9111.9004 | G8: =(F8-F7)/F7 -> 0.041508832
A9: 43934 | B9: 775.67 | C9: =(B9-B8)/B8 -> -0.014233609 | E9: 43934 | F9: 8993.8496 | G9: =(F9-F8)/F8 -> -0.012955671 | I9: 3 | J9: SUMMARY OUTPUT
A10: 43936 | B10: 809.59 | C10: =(B10-B9)/B9 -> 0.043729937 | E10: 43936 | F10: 8925.2998 | G10: =(F10-F9)/F9 -> -0.0076218536 | J10: Regression Statistics
A11: 43937 | B11: 836.19 | C11: =(B11-B10)/B10 -> 0.032856137 | E11: 43937 | F11: 8992.7998 | G11: =(F11-F10)/F10 -> 0.0075627712 | J11: Multiple R | K11: 0.37757134
A12: 43938 | B12: 809.51 | C12: =(B12-B11)/B11 -> -0.031906624 | E12: 43938 | F12: 9266.75 | G12: =(F12-F11)/F11 -> 0.030463282 | J12: R Square | K12: 0.14256011
A13: 43941 | B13: 793.26 | C13: =(B13-B12)/B12 -> -0.020073872 | E13: 43941 | F13: 9261.8496 | G13: =(F13-F12)/F12 -> -0.00052881438 | J13: Adjusted R Square | K13: 0.14198037
A14: 43942 | B14: 795.08 | C14: =(B14-B13)/B13 -> 0.0022943297 | E14: 43942 | F14: 8981.4502 | G14: =(F14-F13)/F13 -> -0.030274667 | J14: Standard Error | K14: 0.011917235
A15: 43943 | B15: 824.36 | C15: =(B15-B14)/B14 -> 0.036826483 | E15: 43943 | F15: 9187.2998 | G15: =(F15-F14)/F14 -> 0.022919418 | J15: Observations | K15: 1481
A16: 43944 | B16: 814.73 | C16: =(B16-B15)/B15 -> -0.01168179 | E16: 43944 | F16: 9313.9004 | G16: =(F16-F15)/F15 -> 0.013779956
A17: 43945 | B17: 813.33 | C17: =(B17-B16)/B16 -> -0.0017183607 | E17: 43945 | F17: 9154.4004 | G17: =(F17-F16)/F16 -> -0.017124942 | J17: ANOVA
A18: 43948 | B18: 838.79 | C18: =(B18-B17)/B17 -> 0.031303407 | E18: 43948 | F18: 9282.2998 | G18: =(F18-F17)/F17 -> 0.013971359 | K18: df | L18: SS | M18: MS | N18: F | O18: Significance F
A19: 43949 | B19: 820.98 | C19: =(B19-B18)/B18 -> -0.021232967 | E19: 43949 | F19: 9380.9004 | G19: =(F19-F18)/F18 -> 0.010622431 | J19: Regression | K19: 1 | L19: 0.034923163 | M19: 0.034923163 | N19: 245.90226 | O19: 2.1991786e-51
A20: 43950 | B20: 817.24 | C20: =(B20-B19)/B19 -> -0.0045555312 | E20: 43950 | F20: 9553.3496 | G20: =(F20-F19)/F19 -> 0.018383014 | J20: Residual | K20: 1479 | L20: 0.21004832 | M20: 0.0001420205
A21: 43951 | B21: 837.57 | C21: =(B21-B20)/B20 -> 0.024876413 | E21: 43951 | F21: 9859.9004 | G21: =(F21-F20)/F20 -> 0.032088303 | J21: Total | K21: 1480 | L21: 0.24497148
A22: 43955 | B22: 815.69 | C22: =(B22-B21)/B21 -> -0.02612319 | E22: 43955 | F22: 9293.5 | G22: =(F22-F21)/F21 -> -0.057444839
A23: 43956 | B23: 814.05 | C23: =(B23-B22)/B22 -> -0.0020105677 | E23: 43956 | F23: 9205.5996 | G23: =(F23-F22)/F22 -> -0.0094582655 | K23: Coefficients | L23: Standard Error | M23: t Stat | N23: P-value | O23: Lower 95% | P23: Upper 95% | Q23: Lower 95.0% | R23: Upper 95.0%
A24: 43957 | B24: 808.81 | C24: =(B24-B23)/B23 -> -0.006436951 | E24: 43957 | F24: 9270.9004 | G24: =(F24-F23)/F23 -> 0.0070935935 | J24: Intercept | K24: 4.4977576e-05 | L24: 0.00031050531 | M24: 0.14485284 | N24: 0.8848468 | O24: -0.00056410009 | P24: 0.00065405524 | Q24: -0.00056410009 | R24: 0.00065405524
A25: 43958 | B25: 801.02 | C25: =(B25-B24)/B24 -> -0.0096314338 | E25: 43958 | F25: 9199.0498 | G25: =(F25-F24)/F24 -> -0.0077501195 | J25: X Variable 1 | K25: 0.49579971 | L25: 0.031617316 | M25: 15.681271 | N25: 2.1991786e-51 | O25: 0.43378015 | P25: 0.55781927 | Q25: 0.43378015 | R25: 0.55781927
A26: 43959 | B26: 831.88 | C26: =(B26-B25)/B25 -> 0.03852588 | E26: 43959 | F26: 9251.5 | G26: =(F26-F25)/F25 -> 0.0057016971
A27: 43962 | B27: 820.62 | C27: =(B27-B26)/B26 -> -0.013535606 | E27: 43962 | F27: 9239.2002 | G27: =(F27-F26)/F26 -> -0.001329493
A28: 43963 | B28: 815.94 | C28: =(B28-B27)/B27 -> -0.005703005 | E28: 43963 | F28: 9196.5498 | G28: =(F28-F27)/F27 -> -0.0046162427
A29: 43964 | B29: 771.57 | C29: =(B29-B28)/B28 -> -0.054378998 | E29: 43964 | F29: 9383.5498 | G29: =(F29-F28)/F28 -> 0.020333713
A30: 43965 | B30: 758.96 | C30: =(B30-B29)/B29 -> -0.0163433 | E30: 43965 | F30: 9142.75 | G30: =(F30-F29)/F29 -> -0.025661909
A31: 43966 | B31: 768.37 | C31: =(B31-B30)/B30 -> 0.012398545 | E31: 43966 | F31: 9136.8496 | G31: =(F31-F30)/F30 -> -0.00064536279
A32: 43969 | B32: 758.86 | C32: =(B32-B31)/B31 -> -0.01237685 | E32: 43969 | F32: 8823.25 | G32: =(F32-F31)/F31 -> -0.03432251
A33: 43970 | B33: 754.66 | C33: =(B33-B32)/B32 -> -0.0055346177 | E33: 43970 | F33: 8879.0996 | G33: =(F33-F32)/F32 -> 0.0063298228
A34: 43971 | B34: 761.81 | C34: =(B34-B33)/B33 -> 0.0094744653 | E34: 43971 | F34: 9066.5498 | G34: =(F34-F33)/F33 -> 0.021111397
A35: 43972 | B35: 761.44 | C35: =(B35-B34)/B34 -> -0.00048568541 | E35: 43972 | F35: 9106.25 | G35: =(F35-F34)/F34 -> 0.0043787545
A36: 43973 | B36: 757.69 | C36: =(B36-B35)/B35 -> -0.0049248792 | E36: 43973 | F36: 9039.25 | G36: =(F36-F35)/F35 -> -0.0073575841
A37: 43977 | B37: 778.25 | C37: =(B37-B36)/B36 -> 0.027135108 | E37: 43977 | F37: 9029.0498 | G37: =(F37-F36)/F36 -> -0.0011284338
... A1485: 46111 | B1485: 1174.8 | C1485: =(B1485-B1484)/B1484 -> -0.015420717 | E1485: 46111 | F1485: 22331.4 | G1485: =(F1485-F1484)/F1484 -> -0.021393856

Sheet Assumptions
B2: Particulars | C2: 2021 | D2: 2022 | E2: 2023 | F2: 2024 | G2: 2025 | H2: 2026
B3: Revenur from Operations | C3: ='Standalone Financials'!C4 -> 14709.41 | D3: ='Standalone Financials'!D4 -> 16896.96 | E3: ='Standalone Financials'!E4 -> 19126.3 | F3: ='Standalone Financials'!F4 -> 24393.89 | G3: ='Standalone Financials'!G4 -> 20201.56 | H3: ='Standalone Financials'!H4 -> 23154.6
B4: Revenue Growth | D4: =('Standalone Financials'!D4-'Standalone Financials'!C4)/'Standalone Financials'!C4 -> 0.14871773 | E4: =('Standalone Financials'!E4-'Standalone Financials'!D4)/'Standalone Financials'!D4 -> 0.13193734 | F4: =('Standalone Financials'!F4-'Standalone Financials'!E4)/'Standalone Financials'!E4 -> 0.27541082 | G4: =('Standalone Financials'!G4-'Standalone Financials'!F4)/'Standalone Financials'!F4 -> -0.17185984 | H4: =('Standalone Financials'!H4-'Standalone Financials'!G4)/'Standalone Financials'!G4 -> 0.14617881
B5: Less:Material Cost | C5: ='Standalone Financials'!C10+'Standalone Financials'!C11+'Standalone Financials'!C13 -> 7616.85 | D5: ='Standalone Financials'!D10+'Standalone Financials'!D11+'Standalone Financials'!D13 -> 9341.74 | E5: ='Standalone Financials'!E10+'Standalone Financials'!E11+'Standalone Financials'!E13 -> 8512.22 | F5: ='Standalone Financials'!F10+'Standalone Financials'!F11+'Standalone Financials'!F13 -> 12809.01 | G5: ='Standalone Financials'!G10+'Standalone Financials'!G11+'Standalone Financials'!G13 -> 10474.18 | H5: ='Standalone Financials'!H10+'Standalone Financials'!H11+'Standalone Financials'!H13 -> 10509.52
B6: Less:Employee Cost | C6: ='Standalone Financials'!C12 -> 1521.3 | D6: ='Standalone Financials'!D12 -> 1635.46 | E6: ='Standalone Financials'!E12 -> 1849.18 | F6: ='Standalone Financials'!F12 -> 2336.06 | G6: ='Standalone Financials'!G12 -> 2023.71 | H6: ='Standalone Financials'!H12 -> 2165.81
B7: Less: Other Expense | C7: ='Standalone Financials'!C14 -> 2042.42 | D7: ='Standalone Financials'!D14 -> 2457.48 | E7: ='Standalone Financials'!E14 -> 4333.92 | F7: ='Standalone Financials'!F14 -> 3474.69 | G7: ='Standalone Financials'!G14 -> 3091.37 | H7: ='Standalone Financials'!H14 -> 5341.44
B8: Total Expense | C8: =SUM(C5:C7) -> 11180.57 | D8: =SUM(D5:D7) -> 13434.68 | E8: =SUM(E5:E7) -> 14695.32 | F8: =SUM(F5:F7) -> 18619.76 | G8: =SUM(G5:G7) -> 15589.26 | H8: =SUM(H5:H7) -> 18016.77
B9: EBITDA | C9: =C3-C8 -> 3528.84 | D9: =D3-D8 -> 3462.28 | E9: =E3-E8 -> 4430.98 | F9: =F3-F8 -> 5774.13 | G9: =G3-G8 -> 4612.3 | H9: =H3-H8 -> 5137.83
B10: Less: Depreciation and Amortization | C10: ='Standalone Financials'!C20 -> 390.19 | D10: ='Standalone Financials'!D20 -> 403.01 | E10: ='Standalone Financials'!E20 -> 428.91 | F10: ='Standalone Financials'!F20 -> 537.78 | G10: ='Standalone Financials'!G20 -> 518.17 | H10: ='Standalone Financials'!H20 -> 699.23
B11: EBIT | C11: =C9-C10 -> 3138.65 | D11: =D9-D10 -> 3059.27 | E11: =E9-E10 -> 4002.07 | F11: =F9-F10 -> 5236.35 | G11: =G9-G10 -> 4094.13 | H11: =H9-H10 -> 4438.6
B12: Add: Non Operating Income/Other Income | C12: ='Standalone Financials'!C6 -> -267.95 | D12: ='Standalone Financials'!D6 -> 214.92 | E12: ='Standalone Financials'!E6 -> 115.5 | F12: ='Standalone Financials'!F6 -> 109.43 | G12: ='Standalone Financials'!G6 -> 269.11 | H12: ='Standalone Financials'!H6 -> 161.13
B13: Less:Interest Expense | C13: ='Standalone Financials'!C18 -> 201.19 | D13: ='Standalone Financials'!D18 -> 154.57 | E13: ='Standalone Financials'!E18 -> 119.29 | F13: ='Standalone Financials'!F18 -> 145.49 | G13: ='Standalone Financials'!G18 -> 136 | H13: ='Standalone Financials'!H18 -> 158.31
B14: EBT | C14: =C11+C12-C13 -> 2669.51 | D14: =D11+D12-D13 -> 3119.62 | E14: =E11+E12-E13 -> 3998.28 | F14: =F11+F12-F13 -> 5200.29 | G14: =G11+G12-G13 -> 4227.24 | H14: =H11+H12-H13 -> 4441.42
B15: Less: Tax | C15: ='Standalone Financials'!C23 -> 738.91 | D15: ='Standalone Financials'!D23 -> 865.45 | E15: ='Standalone Financials'!E23 -> 1039.62 | F15: ='Standalone Financials'!F23 -> 1356.03 | G15: ='Standalone Financials'!G23 -> 1132.97 | H15: ='Standalone Financials'!H23 -> 1065.05
B16: Less:Non Controlling Interest/Minority Interest | C16: 0 | D16: 0 | E16: 0 | F16: 0 | G16: 0 | H16: 0
B17: PAT | C17: =C14-C15-C16 -> 1930.6 | D17: =D14-D15-D16 -> 2254.17 | E17: =E14-E15-E16 -> 2958.66 | F17: =F14-F15-F16 -> 3844.26 | G17: =G14-G15-G16 -> 3094.27 | H17: =H14-H15-H16 -> 3376.37
B19: Historical Growth
B20: Average Growth | C20: =AVERAGE(D4:H4) -> 0.10607697
B21: CAGR | C21: =(H3/C3)^(1/5)-1 -> 0.094985595
B22: Margin Analysis
B23: EBITDA Margin | C23: =C9/C3 -> 0.23990357 | D23: =D9/D3 -> 0.2049055 | E23: =E9/E3 -> 0.23166948 | F23: =F9/F3 -> 0.23670395 | G23: =G9/G3 -> 0.22831405 | H23: =H9/H3 -> 0.22189241
B24: EBIT Margin | C24: =C11/C3 -> 0.21337702 | D24: =D11/D3 -> 0.18105446 | E24: =E11/E3 -> 0.20924434 | F24: =F11/F3 -> 0.21465826 | G24: =G11/G3 -> 0.20266405 | H24: =H11/H3 -> 0.19169409
B25: EBT Margin | C25: =C14/C3 -> 0.18148315 | D25: =D14/D3 -> 0.18462611 | E25: =E14/E3 -> 0.20904618 | F25: =F14/F3 -> 0.21318002 | G25: =G14/G3 -> 0.20925315 | H25: =H14/H3 -> 0.19181588
B26: PAT Margin | C26: =C17/C3 -> 0.13124932 | D26: =D17/D3 -> 0.13340684 | E26: =E17/E3 -> 0.15469066 | F26: =F17/F3 -> 0.1575911 | G26: =G17/G3 -> 0.15316985 | H26: =H17/H3 -> 0.14581854
B28: Tax Rate
B29: Effective Tax Rate | C29: =C15/C14 -> 0.27679612 | D29: =D15/D14 -> 0.27742161 | E29: =E15/E14 -> 0.26001681 | F29: =F15/F14 -> 0.26076046 | G29: =G15/G14 -> 0.26801648 | H29: =H15/H14 -> 0.23979943
B30: Marginal Tax Rate | C30: 0.25 | D30: 0.25 | E30: 0.25 | F30: 0.25 | G30: 0.25 | H30: 0.25
B32: Return on Capital
B33: EBIT(1-t) | C33: =C11*(1-C30) -> 2353.9875 | D33: =D11*(1-D30) -> 2294.4525 | E33: =E11*(1-E30) -> 3001.5525 | F33: =F11*(1-F30) -> 3927.2625 | G33: =G11*(1-G30) -> 3070.5975 | H33: =H11*(1-H30) -> 3328.95
B34: Book Equity | C34: ='Standalone Financials'!Q3+'Standalone Financials'!Q4 -> 1946 | D34: ='Standalone Financials'!R3+'Standalone Financials'!R4 -> 2459 | E34: ='Standalone Financials'!S3+'Standalone Financials'!S4 -> 2459 | F34: ='Standalone Financials'!T3+'Standalone Financials'!T4 -> 3340 | G34: ='Standalone Financials'!U3+'Standalone Financials'!U4 -> 4117 | H34: ='Standalone Financials'!V3+'Standalone Financials'!V4 -> 5309
B35: Book Debt | C35: ='Standalone Financials'!Q6+'Standalone Financials'!Q7 -> 34 | D35: ='Standalone Financials'!R6+'Standalone Financials'!R7 -> 30 | E35: ='Standalone Financials'!S6+'Standalone Financials'!S7 -> 30 | F35: ='Standalone Financials'!T6+'Standalone Financials'!T7 -> 31 | G35: ='Standalone Financials'!U6+'Standalone Financials'!U7 -> 753 | H35: ='Standalone Financials'!V6+'Standalone Financials'!V7 -> 24
B36: Cash and Cash Equivalents | C36: ='Standalone Financials'!Q32 -> 735 | D36: ='Standalone Financials'!R32 -> 946 | E36: ='Standalone Financials'!S32 -> 946 | F36: ='Standalone Financials'!T32 -> 779 | G36: ='Standalone Financials'!U32 -> 96 | H36: ='Standalone Financials'!V32 -> 1341
B37: Capital Employed | C37: =C34+C35+C36 -> 2715 | D37: =D34+D35+D36 -> 3435 | E37: =E34+E35+E36 -> 3435 | F37: =F34+F35+F36 -> 4150 | G37: =G34+G35+G36 -> 4966 | H37: =H34+H35+H36 -> 6674
B39: Pre Tax Return on Capital | C39: =C11/C37 -> 1.1560405 | D39: =D11/D37 -> 0.89061718 | E39: =E11/E37 -> 1.1650859 | F39: =F11/F37 -> 1.2617711 | G39: =G11/G37 -> 0.82443214 | H39: =H11/H37 -> 0.66505844
B40: Post Tax Return on Capital | C40: =C33/C37 -> 0.86703039 | D40: =D33/D37 -> 0.66796288 | E40: =E33/E37 -> 0.87381441 | F40: =F33/F37 -> 0.94632831 | G40: =G33/G37 -> 0.6183241 | H40: =H33/H37 -> 0.49879383
B42: Growth Summary
B43: Average Revenue Growth | C43: =AVERAGE(D4:H4) -> 0.10607697
B44: Revenue CAGR | C44: =(H3/C3)^(1/5)-1 -> 0.094985595
B46: Growth in EBIT | C46: =FCFF!C13*G40 -> 0.0038401834

Sheet Fixed asset schedule
B2: Particulars | C2: 2021 | D2: 2022 | E2: 2023 | F2: 2024 | G2: 2025 | H2: 2026
B3: Beginning Balance (Net Fixed Assets) | D3: =C7 -> 2995 | E3: =D7 -> 3044 | F3: =E7 -> 3044 | G3: =F7 -> 3460 | H3: =G7 -> 5474
B4: Add: Net Purchases (Capex) | D4: =D5-D3 -> 452.01 | E4: =E5-E3 -> 428.91 | F4: =F5-F3 -> 953.78 | G4: =G5-G3 -> 2532.17 | H4: =H5-H3 -> 1515.23
B5: Total Fixed Assets (Gross) | C5: =C7+C6 -> 3385.19 | D5: =D6+D7 -> 3447.01 | E5: =E6+E7 -> 3472.91 | F5: =F6+F7 -> 3997.78 | G5: =G6+G7 -> 5992.17 | H5: =H6+H7 -> 6989.23
B6: Less: Depreciation & Amortisation | C6: ='Standalone Financials'!C20 -> 390.19 | D6: ='Standalone Financials'!D20 -> 403.01 | E6: ='Standalone Financials'!E20 -> 428.91 | F6: ='Standalone Financials'!F20 -> 537.78 | G6: ='Standalone Financials'!G20 -> 518.17 | H6: ='Standalone Financials'!H20 -> 699.23
B7: Closing Balance (Net Fixed Assets) | C7: ='Standalone Financials'!Q14 -> 2995 | D7: ='Standalone Financials'!R14 -> 3044 | E7: ='Standalone Financials'!S14 -> 3044 | F7: ='Standalone Financials'!T14 -> 3460 | G7: ='Standalone Financials'!U14 -> 5474 | H7: ='Standalone Financials'!V14 -> 6290
B9: Net Capital Expenditure | D9: =D4-D6 -> 49 | E9: =E4-E6 -> 0 | F9: =F4-F6 -> 416 | G9: =G4-G6 -> 2014 | H9: =H4-H6 -> 816
B10: Net Capex / Sales (%) | D10: =D9/'Standalone Financials'!C5 -> 0.0033312009 | E10: =E9/'Standalone Financials'!D5 -> 0 | F10: =F9/'Standalone Financials'!E5 -> 0.021750156 | G10: =G9/'Standalone Financials'!F5 -> 0.082561658 | H10: =H9/'Standalone Financials'!G5 -> 0.04039292
B12: Median Capital expenditure /Sales percentage | C12: =MEDIAN(D10:H10) -> 0.021750156
B13: Average Capital expenditure /Sales percentage | C13: =AVERAGE(D10:H10) -> 0.029607187

Sheet Change In WC
B2: Particulars | C2: 2021 | D2: 2022 | E2: 2023 | F2: 2024 | G2: 2025 | H2: 2026
B3: Inventories | C3: ='Standalone Financials'!Q30 -> 1593 | D3: ='Standalone Financials'!R30 -> 1929 | E3: ='Standalone Financials'!S30 -> 1929 | F3: ='Standalone Financials'!T30 -> 2089 | G3: ='Standalone Financials'!U30 -> 2850 | H3: ='Standalone Financials'!V30 -> 2569
B4: Trade Receivables | C4: ='Standalone Financials'!Q31 -> 166 | D4: ='Standalone Financials'!R31 -> 192 | E4: ='Standalone Financials'!S31 -> 192 | F4: ='Standalone Financials'!T31 -> 300 | G4: ='Standalone Financials'!U31 -> 363 | H4: ='Standalone Financials'!V31 -> 329
B5: Trade Payables | C5: ='Standalone Financials'!Q10 -> 1748 | D5: ='Standalone Financials'!R10 -> 2121 | E5: ='Standalone Financials'!S10 -> 2121 | F5: ='Standalone Financials'!T10 -> 2812 | G5: ='Standalone Financials'!U10 -> 2624 | H5: ='Standalone Financials'!V10 -> 3160
B6: Non-Cash Working Capital | C6: =C3+C4-C5 -> 11 | D6: =D3+D4-D5 -> 0 | E6: =E3+E4-E5 -> 0 | F6: =F3+F4-F5 -> -423 | G6: =G3+G4-G5 -> 589 | H6: =H3+H4-H5 -> -262
B7: Change in Working Capital | D7: =D6-C6 -> -11 | E7: =E6-D6 -> 0 | F7: =F6-E6 -> -423 | G7: =G6-F6 -> 1012 | H7: =H6-G6 -> -851
B8: Change in WC / Sales (%) | D8: =(D7/'Standalone Financials'!C5) -> -0.00074782061 | E8: =(E7/'Standalone Financials'!D5) -> 0 | F8: =(F7/'Standalone Financials'!E5) -> -0.022116144 | G8: =(G7/'Standalone Financials'!F5) -> 0.041485798 | H8: =(H7/'Standalone Financials'!G5) -> -0.04212546
B10: Median Non-Cash WC / Sales (%) | C10: =MEDIAN(D8:H8) -> -0.00074782061

Sheet FCFF
B2: Particulars | C2: 2021 | D2: 2022 | E2: 2023 | F2: 2024 | G2: 2025 | H2: 2026
B3: EBIT | C3: =Assumptions!C11 -> 3138.65 | D3: =Assumptions!D11 -> 3059.27 | E3: =Assumptions!E11 -> 4002.07 | F3: =Assumptions!F11 -> 5236.35 | G3: =Assumptions!G11 -> 4094.13 | H3: =Assumptions!H11 -> 4438.6
B4: Less: Tax on EBIT (25%) | C4: =25%*C3 -> 784.6625 | D4: =25%*D3 -> 764.8175 | E4: =25%*E3 -> 1000.5175 | F4: =25%*F3 -> 1309.0875 | G4: =25%*G3 -> 1023.5325 | H4: =25%*H3 -> 1109.65
B5: NOPAT [EBIT × (1 − Tax)] | C5: =C3-C4 -> 2353.9875 | D5: =D3-D4 -> 2294.4525 | E5: =E3-E4 -> 3001.5525 | F5: =F3-F4 -> 3927.2625 | G5: =G3-G4 -> 3070.5975 | H5: =H3-H4 -> 3328.95
B6: Less: Net Capital Expenditure | D6: ='Fixed asset schedule'!D9 -> 49 | E6: ='Fixed asset schedule'!E9 -> 0 | F6: ='Fixed asset schedule'!F9 -> 416 | G6: ='Fixed asset schedule'!G9 -> 2014 | H6: ='Fixed asset schedule'!H9 -> 816
B7: Less: Change in Working Capital | D7: ='Change In WC'!D7 -> -11 | E7: ='Change In WC'!E7 -> 0 | F7: ='Change In WC'!F7 -> -423 | G7: ='Change In WC'!G7 -> 1012 | H7: ='Change In WC'!H7 -> -851
B8: Reinvestment (Capex + ΔWCL) | C8: =SUM(C6:C7) -> 0 | D8: =SUM(D6:D7) -> 38 | E8: =SUM(E6:E7) -> 0 | F8: =SUM(F6:F7) -> -7 | G8: =SUM(G6:G7) -> 3026 | H8: =SUM(H6:H7) -> -35
B9: Free Cash Flow to Firm (FCFF) | C9: =C5-C8 -> 2353.9875 | D9: =D5-D8 -> 2256.4525 | E9: =E5-E8 -> 3001.5525 | F9: =F5-F8 -> 3934.2625 | G9: =G5-G8 -> 44.5975 | H9: =H5-H8 -> 3363.95
B11: Reinvestment Rate | D11: =D8/D3 -> 0.012421264 | E11: =E8/E3 -> 0 | F11: =F8/F3 -> -0.001336809 | G11: =G8/G3 -> 0.73910697 | H11: =H8/H3 -> -0.0078853693
B13: Median Reinvestment rate /Sales percentage | C13: =MEDIAN(D11:G11) -> 0.0062106319
B14: Average Reinvestment rate /Sales percentage | C14: =AVERAGE(D11:G11) -> 0.18754786

Sheet Cost Of Capital
B2: Nestle Ltd.
B3: Weighted Average Cost of Capital
B4: Capital Structure | C4: Amt. | E4: Cost of Equity | F4: Amt. | H4: Cost of Debt | I4: Amt.
B5: Total Debt | C5: ='Standalone Financials'!U6+'Standalone Financials'!U7 -> 753 | E5: Risk free rate(Rf) | F5: 0.06737 | H5: Cost of debt* | I5: ='Standalone Financials'!G18/C5 -> 0.18061089
B6: Total Equity | C6: ='Standalone Financials'!U3+'Standalone Financials'!U4 -> 4117 | E6: Beta | F6: =Beta!K5 -> 0.49579971 | H6: Tax rate | I6: =Assumptions!G30 -> 0.25
B7: Total Mix | C7: =SUM(C5:C6) -> 4870 | E7: Market risk premium | F7: 0.0744 | H7: Cost of Debt after tax | I7: =I5*(1-I6) -> 0.13545817
B8: % of Debt | C8: =C5/C7 -> 0.15462012 | E8: Cost of equity | F8: =F5+F6*F7 -> 0.1042575
B9: % of Equity | C9: =C6/C7 -> 0.84537988 | H9: Spread(Wacc-Growth) | I9: =E16-0.04 -> 0.06908175
B10: Debt to Equity | C10: =C5/C6 -> 0.18290017
B12: WACC
B13: Source | C13: Weight | D13: Cost | E13: Weighted Cost
B14: Debt | C14: =C8 -> 0.15462012 | D14: =I7 -> 0.13545817 | E14: =C14*D14 -> 0.020944559
B15: Equity | C15: =C9 -> 0.84537988 | D15: =F8 -> 0.1042575 | E15: =C15*D15 -> 0.088137191
B16: WACC | E16: =SUM(E14:E15) -> 0.10908175

Sheet Raw FS valuation
A2: S.No. | B2: Name | C2: CMP Rs. | D2: P/E | E2: Mar Cap Rs.Cr. | F2: Div Yld % | G2: Qtr Profit Var % | H2: Sales Qtr Rs.Cr. | I2: Qtr Sales Var % | J2: ROCE % | K2: No. Eq. Shares Cr. | L2: Debt Rs.Cr. | M2: NP 12M Rs.Cr. | N2: Cash End Rs.Cr. | O2: Sales Rs. Cr. | P2: EV / EBITDA | Q2: OP 12M Rs. Cr.
A3: 1 | B3: Nestle India | C3: 1457.5 | D3: 81.4 | E3: 281051.81 | F3: 0.82 | G3: 28.84 | H3: 6747.79 | I3: 22.6 | J3: 84.21 | K3: 192.83 | L3: 444.16 | M3: 3544.6 | N3: 1340.87 | O3: 23154.6 | P3: 52.4 | Q3: 5306.06
A4: 2 | B4: Britannia Inds. | C4: 5397.5 | D4: 51.29 | E4: 130008.69 | F4: 1.4 | G4: 21.14 | H4: 4718.92 | I4: 6.47 | J4: 56.02 | K4: 24.09 | L4: 1380.28 | M4: 2537.01 | N4: 352.44 | O4: 19151.59 | P4: 35.05 | Q4: 3514.34
A5: 3 | B5: Bikaji Foods | C5: 676.35 | D5: 67.94 | E5: 16958.58 | F5: 0.15 | G5: 117.64 | H5: 790.01 | I5: 10.51 | J5: 18.16 | K5: 25.07 | L5: 309.73 | M5: 238.46 | N5: 219.05 | O5: 2883.95 | P5: 38.54 | Q5: 396.92
A6: 4 | B6: Zydus Wellness | C6: 510 | D6: 67.49 | E6: 16226.14 | F6: 0.24 | G6: -643.12 | H6: 964.9 | I6: 108.9 | J6: 6.16 | K6: 31.82 | L6: 3042 | M6: 207.1 | N6: 73.9 | O6: 3389.4 | P6: 43.95 | Q6: 429.6
A7: 5 | B7: The Bombay Burmah | C7: 1536.9 | D7: 8.91 | E7: 10723.26 | F7: 1.12 | G7: 39.72 | H7: 4817.99 | I7: 6.62 | J7: 33 | K7: 6.98 | L7: 1590.43 | M7: 2499.25 | N7: 842.81 | O7: 19538.62 | P7: 3.06 | Q7: 3431.64
A8: 6 | B8: Mrs Bectors | C8: 184.05 | D8: 48.05 | E8: 5650.18 | F8: 0.69 | G8: 21.13 | H8: 496.65 | I8: 8.54 | J8: 16.39 | K8: 30.7 | L8: 182.19 | M8: 117.7 | N8: 188.55 | O8: 1861.62 | P8: 22.91 | Q8: 221.36
A9: 7 | B9: Gopal Snacks | C9: 294.5 | D9: 82.44 | E9: 3670.12 | F9: 0.33 | G9: 119.01 | H9: 409.63 | I9: 29.02 | J9: 12.14 | K9: 12.46 | L9: 154.03 | M9: 73.65 | N9: 0.75 | O9: 1508.23 | P9: 36.17 | Q9: 101.25

Sheet Relative VAluation
B2: Relative Valuation - Siemens Ltd
B4: Figures in Crore
B5: Comparable Company Valuation
B6: Company Name | C6: Market Data | J6: Financials | O6: Valuation
C7: No. of shares | D7: Share Price | E7: Equity value | F7: Debt | G7: cash | H7: Enterprises value | J7: Revenue | K7: EBITDA | L7: Net Profit | M7: EPS | O7: EV/Revenue | P7: EV/EBITDA | Q7: P/E Ratio
B8: Nestle India | C8: ='Raw FS valuation'!K3 -> 192.83 | D8: ='Raw FS valuation'!C3 -> 1457.5 | E8: =C8*D8 -> 281049.73 | F8: ='Raw FS valuation'!L3 -> 444.16 | G8: ='Raw FS valuation'!N3 -> 1340.87 | H8: =E8+F8-G8 -> 280153.02 | J8: ='Raw FS valuation'!O3 -> 23154.6 | K8: ='Raw FS valuation'!Q3 -> 5306.06 | L8: ='Raw FS valuation'!M3 -> 3544.6 | M8: =L8/C8 -> 18.381995 | O8: =H8/J8 -> 12.099238 | P8: =H8/K8 -> 52.79869 | Q8: =D8/M8 -> 79.289546
