Workbook

Sheet About
B5: About the Company
B6: Tech Mahindra Ltd provides comprehensive range of IT services, including IT enabled service, application development and maintenance, consulting and enterprise business solutions, etc. to a diversified base of corporate customers in a wide range of industries.
B9: Key Points
B10: Parentage
B11: The company is a subsidiary of the Mahindra Group, a leading global conglomerate with operations in 100+ countries. The group manages 150 companies across 22 major industries, including renewable energy, agriculture, logistics, hospitality, real estate, aerospace, automotive components, and consulting services, etc.
B15: Services Offerings
B16: The company provides a full spectrum of services including consulting, information technology, enterprise applications, business process services, engineering services, network services, customer experience & design services, AI & analytics, and cloud & infrastructure services.
B20: AI Developments
B21: The company highlighted progresses in supporting clients to move from AI experimentation to execution across IT, operations, processes, experience, and business transformation, with AI becoming a core execution engine in large, multi-year enterprise programs. Under the Indian AI Mission, it is developing an education-focused LLM and localizing TechM Orion in Hindi to improve accessibility and adoption. Additionally, over 80,000 employees have been trained in AI and GenAI, and more than 80% of the sales and support workforce is enabled with AI.
B26: New Launch & Collaborations
B27: Company entered multiple partnerships, including an MoU with the University of Texas at Dallas for AI-led innovation, research, and skill development, along with plans to launch its first U.S. Makers Lab. It also signed MoUs with Strangeworks for quantum optimization solutions across key industries, collaborated with Germany’s DFKI on next-generation smart factory solutions, and partnered with Arviem to deliver IoT- and analytics-driven supply chain visibility solutions.

Sheet Promoters
B2: Particulars | C2: 45078 | D2: 45170 | E2: 45261 | F2: 45352 | G2: 45444 | H2: 45536 | I2: 45627 | J2: 45717 | K2: 45809 | L2: 45901 | M2: 45992 | N2: 46082
B3: Promoters - | C3: 0.3515 | D3: 0.3513 | E3: 0.351 | F3: 0.3508 | G3: 0.3504 | H3: 0.3502 | I3: 0.3501 | J3: 0.35 | K3: 0.3499 | L3: 0.3498 | M3: 0.3497 | N3: 0.3497
B4: Mahindra & Mahindra Limited | C4: 25.45 | D4: 25.43 | E4: 25.41 | F4: 25.39 | G4: 25.36 | H4: 25.35 | I4: 25.34 | J4: 25.33 | K4: 25.33 | L4: 25.32 | M4: 25.32 | N4: 25.31
B5: TMLBenefitTrustThroughMrManojRaghunathBhatTrusteeT... | C5: 9.67 | D5: 9.66 | E5: 9.65 | F5: 9.65 | G5: 9.64
B6: TMLBenefitTrustThroughMrAmarjyotiBaruaTrusteeThetr... | H6: 9.63 | I6: 9.63 | J6: 9.63 | K6: 9.62
B7: TML Benefit Trust Through Amarjyoti Barua | L7: 9.62
B8: TML Benefit Trust through Puneet Renjhen | M8: 9.62 | N8: 9.62
B9: Mahindra-Bt Investment Company (Mauritius) Limited | C9: 0.02 | D9: 0.02 | E9: 0.02 | F9: 0.02 | G9: 0.02 | H9: 0.02 | I9: 0.02 | J9: 0.02 | K9: 0.02 | L9: 0.02 | M9: 0.02
B10: Mahindra Holdings Limited | C10: 0.02 | D10: 0.02 | E10: 0.02 | F10: 0.02 | G10: 0.02 | H10: 0.02 | I10: 0.02 | J10: 0.02 | K10: 0.02 | L10: 0.02 | M10: 0.02 | N10: 0.02
B11: Mahindra Investment Company Mauritius Limited [For... | N11: 0.02
B12: FIIs - | C12: 0.2569 | D12: 0.2622 | E12: 0.2458 | F12: 0.2415 | G12: 0.2327 | H12: 0.2367 | I12: 0.2419 | J12: 0.2295 | K12: 0.2328 | L12: 0.206 | M12: 0.1794 | N12: 0.1859
B13: First Sentier Investors Icvc - Stewart Investors A... | C13: 2.15 | D13: 2.27 | E13: 1.78 | F13: 1.67 | G13: 1.53 | H13: 1.53 | I13: 1.45 | J13: 1.39 | K13: 1.3 | L13: 1.03
B14: Government Pension Fund Global | C14: 2.11 | D14: 2.03 | E14: 1.42 | F14: 1.32 | G14: 1.64 | H14: 1.32 | I14: 1.11 | J14: 1.06 | K14: 1.18 | L14: 1.19 | M14: 1.17
B15: DIIs - | C15: 0.2686 | D15: 0.2703 | E15: 0.2891 | F15: 0.2942 | G15: 0.3066 | H15: 0.309 | I15: 0.3073 | J15: 0.3213 | K15: 0.3213 | L15: 0.3464 | M15: 0.3779 | N15: 0.3734
B16: Life Insurance Corporation Of India | C16: 9.47 | D16: 9.64 | E16: 9.64 | F16: 10.05 | G16: 10.41 | H16: 10.64 | I16: 10.14 | J16: 10.14 | K16: 10.31 | L16: 11.04 | M16: 11.49 | N16: 11.44
B17: Sbi Nifty 50 Etf | C17: 3.94 | D17: 3.35 | E17: 3.44 | F17: 3.54 | G17: 3.78 | H17: 3.97 | I17: 3.92 | J17: 3.91 | K17: 3.84 | L17: 4.2 | M17: 4.69 | N17: 4.69
B18: Icici Prudential Technology Fund | I18: 1.92 | J18: 1.95 | K18: 1.91 | L18: 2.19 | M18: 2.43 | N18: 2.53
B19: Icici Prudential Bluechip Fund | C19: 1.84 | D19: 2.02 | E19: 2.72 | F19: 2.33 | G19: 2.1 | H19: 1.89
B20: Kotak Flexicap Fund | H20: 1.82 | I20: 1.93 | J20: 2.45 | K20: 2.28 | L20: 1.93 | M20: 2.18 | N20: 1.8
B21: Aditya Birla Sun Life Trustee Private Limited A/C ... | L21: 1.78 | M21: 1.79 | N21: 1.79
B22: Aditya Birla Sun Life Trustee Private Limited A/C ... | J22: 1.4 | K22: 1.54
B23: Uti Nifty 50 Etf | H23: 1.26 | I23: 1.46 | J23: 1.49 | K23: 1.28 | L23: 1.3 | M23: 1.39 | N23: 1.44
B24: Hdfc Trustee Company Limited-Hdfc Flexi Cap Fund | C24: 1.3 | D24: 1.13 | E24: 1.29 | F24: 1.37 | G24: 1.53 | H24: 1.42 | I24: 1 | J24: 1.05
B25: Nps Trust- A/C Sbi Pension Fund Scheme - State Govt | C25: 1.12 | D25: 1.01 | E25: 1.12 | F25: 1.21 | G25: 1.08 | I25: 1.21 | J25: 1.27 | K25: 1.17 | L25: 1.33 | M25: 1.47 | N25: 1.83
B26: Sbi Life Insurance Co. Ltd | K26: 1.01 | L26: 1.27 | M26: 1.33 | N26: 1.3
B27: Uti - Nifty Exchange Traded Fund | C27: 1.18 | D27: 1.1 | E27: 1.18 | F27: 1.24 | G27: 1.28
B28: Nippon Life India Trustee Ltd-A/C Nippon India Etf... | L28: 1.06 | M28: 1.08 | N28: 1.34
B29: Tata Digital India Fund | F29: 1.04 | G29: 1.07 | H29: 1.04 | I29: 1.08 | J29: 1.22 | K29: 1.18 | L29: 1.23 | M29: 1.3
B30: Kotak Emerging Equity Scheme | G30: 1.09
B31: Government - | C31: 0.0017 | D31: 0.0017 | E31: 0.0017 | F31: 0.0017 | G31: 0.0017 | H31: 0.0017 | I31: 0.0017 | J31: 0.0017 | K31: 0.0017 | L31: 0.0017 | M31: 0.0017 | N31: 0.0017
B32: Public - | C32: 0.1211 | D32: 0.1144 | E32: 0.1122 | F32: 0.1116 | G32: 0.1084 | H32: 0.1023 | I32: 0.0988 | J32: 0.0974 | K32: 0.0943 | L32: 0.0961 | M32: 0.0914 | N32: 0.0894
B33: No. of Shareholders | C33: 929827 | D33: 885590 | E33: 867373 | F33: 848484 | G33: 826284 | H33: 774997 | I33: 761383 | J33: 761701 | K33: 748176 | L33: 766782 | M33: 739883 | N33: 738055

Sheet Consolidated FS
B2: Profit & Loss Tech Mahindra Ltd. | P2: Balance sheet Tech Mahindra Ltd.
B3: Profit & Loss for the year ended 31 march 2025 | J3: % Change | P3: Balance sheet of the year 2025 | X3: % Change
B4: Particulars | C4: 43891 | D4: 44256 | E4: 44621 | F4: 44986 | G4: 45352 | H4: 45717 | J4: 44256 | K4: 44621 | L4: 44986 | M4: 45352 | N4: 45717 | P4: Particulars | Q4: 43891 | R4: 44256 | S4: 44621 | T4: 44986 | U4: 45352 | V4: 45717 | X4: 44256 | Y4: 44621 | Z4: 44986 | AA4: 45352 | AB4: 45717
B5: Sales | C5: 36868 | D5: 37855 | E5: 44646 | F5: 53290 | G5: 51996 | H5: 52988 | J5: =(D5-C5)/C5 -> 0.026771184 | K5: =(E5-D5)/D5 -> 0.17939506 | L5: =(F5-E5)/E5 -> 0.19361197 | M5: =(G5-F5)/F5 -> -0.024282229 | N5: =(H5-G5)/G5 -> 0.019078391 | P5: Equity Capital | Q5: 436 | R5: 437 | S5: 439 | T5: 440 | U5: 441 | V5: 442 | X5: =(R5-Q5)/Q5 -> 0.002293578 | Y5: =(S5-R5)/R5 -> 0.004576659 | Z5: =(T5-S5)/S5 -> 0.0022779043 | AA5: =(U5-T5)/T5 -> 0.0022727273 | AB5: =(V5-U5)/U5 -> 0.0022675737
B6: Sales Growth % | C6: 0.0612 | D6: 0.0268 | E6: 0.1794 | F6: 0.1936 | G6: -0.0243 | H6: 0.0191 | J6: =(D6-C6)/C6 -> -0.5620915 | K6: =(E6-D6)/D6 -> 5.6940299 | L6: =(F6-E6)/E6 -> 0.079152731 | M6: =(G6-F6)/F6 -> -1.1255165 | N6: =(H6-G6)/G6 -> -1.7860082 | P6: Reserves | Q6: 21377 | R6: 24428 | S6: 26447 | T6: 27484 | U6: 26228 | V6: 26919 | X6: =(R6-Q6)/Q6 -> 0.14272349 | Y6: =(S6-R6)/R6 -> 0.082651056 | Z6: =(T6-S6)/S6 -> 0.039210496 | AA6: =(U6-T6)/T6 -> -0.045699316 | AB6: =(V6-U6)/U6 -> 0.02634589
B7: Expenses | C7: 31365 | D7: 31059 | E7: 36626 | F7: 45527 | G7: 47489 | H7: 46024 | J7: =(D7-C7)/C7 -> -0.0097560976 | K7: =(E7-D7)/D7 -> 0.17923951 | L7: =(F7-E7)/E7 -> 0.24302408 | M7: =(G7-F7)/F7 -> 0.043095306 | N7: =(H7-G7)/G7 -> -0.030849249 | P7: Borrowings | Q7: 3670 | R7: 2901 | S7: 2618 | T7: 2740 | U7: 2537 | V7: 2025 | X7: =(R7-Q7)/Q7 -> -0.20953678 | Y7: =(S7-R7)/R7 -> -0.097552568 | Z7: =(T7-S7)/S7 -> 0.046600458 | AA7: =(U7-T7)/T7 -> -0.074087591 | AB7: =(V7-U7)/U7 -> -0.20181317
B8: Manufacturing Cost % | C8: 0.23 | D8: 0.23 | E8: 0.26 | F8: 0.26 | G8: 0.25 | H8: 0.23 | J8: =(D8-C8)/C8 -> 0 | K8: =(E8-D8)/D8 -> 0.13043478 | L8: =(F8-E8)/E8 -> 0 | M8: =(G8-F8)/F8 -> -0.038461538 | N8: =(H8-G8)/G8 -> -0.08 | P8: Long term Borrowings | Q8: 179 | R8: 166 | S8: 142 | T8: 129 | U8: 102 | V8: 0 | X8: =(R8-Q8)/Q8 -> -0.072625698 | Y8: =(S8-R8)/R8 -> -0.14457831 | Z8: =(T8-S8)/S8 -> -0.091549296 | AA8: =(U8-T8)/T8 -> -0.20930233 | AB8: =(V8-U8)/U8 -> -1
B9: Employee Cost % | C9: 0.51 | D9: 0.51 | E9: 0.5 | F9: 0.52 | G9: 0.56 | H9: 0.56 | J9: =(D9-C9)/C9 -> 0 | K9: =(E9-D9)/D9 -> -0.019607843 | L9: =(F9-E9)/E9 -> 0.04 | M9: =(G9-F9)/F9 -> 0.076923077 | N9: =(H9-G9)/G9 -> 0 | P9: Short term Borrowings | Q9: 2250 | R9: 1496 | S9: 1440 | T9: 1449 | U9: 1428 | V9: 471 | X9: =(R9-Q9)/Q9 -> -0.33511111 | Y9: =(S9-R9)/R9 -> -0.037433155 | Z9: =(T9-S9)/S9 -> 0.00625 | AA9: =(U9-T9)/T9 -> -0.014492754 | AB9: =(V9-U9)/U9 -> -0.67016807
B10: Other Cost % | C10: 0.11 | D10: 0.08 | E10: 0.07 | F10: 0.08 | G10: 0.1 | H10: 0.08 | J10: =(D10-C10)/C10 -> -0.27272727 | K10: =(E10-D10)/D10 -> -0.125 | L10: =(F10-E10)/E10 -> 0.14285714 | M10: =(G10-F10)/F10 -> 0.25 | N10: =(H10-G10)/G10 -> -0.2 | P10: Lease Liabilities | Q10: 1200 | R10: 1208 | S10: 1037 | T10: 1162 | U10: 1006 | V10: 1554 | X10: =(R10-Q10)/Q10 -> 0.0066666667 | Y10: =(S10-R10)/R10 -> -0.14155629 | Z10: =(T10-S10)/S10 -> 0.12054002 | AA10: =(U10-T10)/T10 -> -0.13425129 | AB10: =(V10-U10)/U10 -> 0.54473161
B11: Operating Profit | C11: 5503 | D11: 6796 | E11: 8020 | F11: 7763 | G11: 4506 | H11: 6964 | J11: =(D11-C11)/C11 -> 0.23496275 | K11: =(E11-D11)/D11 -> 0.18010594 | L11: =(F11-E11)/E11 -> -0.032044888 | M11: =(G11-F11)/F11 -> -0.4195543 | N11: =(H11-G11)/G11 -> 0.5454949 | P11: Other Borrowings | Q11: 42 | R11: 31 | S11: 0 | T11: 0 | U11: 0 | V11: 0 | X11: =(R11-Q11)/Q11 -> -0.26190476 | Y11: =(S11-R11)/R11 -> -1
B12: OPM % | C12: 0.15 | D12: 0.18 | E12: 0.18 | F12: 0.15 | G12: 0.09 | H12: 0.13 | J12: =(D12-C12)/C12 -> 0.2 | K12: =(E12-D12)/D12 -> 0 | L12: =(F12-E12)/E12 -> -0.16666667 | M12: =(G12-F12)/F12 -> -0.4 | N12: =(H12-G12)/G12 -> 0.44444444 | P12: Other Liabilities | Q12: 11834 | R12: 11836 | S12: 14911 | T12: 15162 | U12: 13943 | V12: 14880 | X12: =(R12-Q12)/Q12 -> 0.00016900456 | Y12: =(S12-R12)/R12 -> 0.25980061 | Z12: =(T12-S12)/S12 -> 0.01683321 | AA12: =(U12-T12)/T12 -> -0.080398364 | AB12: =(V12-U12)/U12 -> 0.06720218
B13: Other Income | C13: 1192 | D13: 788 | E13: 1115 | F13: 965 | G13: 927 | H13: 864 | J13: =(D13-C13)/C13 -> -0.33892617 | K13: =(E13-D13)/D13 -> 0.41497462 | L13: =(F13-E13)/E13 -> -0.13452915 | M13: =(G13-F13)/F13 -> -0.039378238 | N13: =(H13-G13)/G13 -> -0.067961165 | P13: Non controlling int | Q13: 393 | R13: 380 | S13: 495 | T13: 470 | U13: 477 | V13: 430 | X13: =(R13-Q13)/Q13 -> -0.03307888 | Y13: =(S13-R13)/R13 -> 0.30263158 | Z13: =(T13-S13)/S13 -> -0.050505051 | AA13: =(U13-T13)/T13 -> 0.014893617 | AB13: =(V13-U13)/U13 -> -0.098532495
B14: Exceptional items | C14: 8 | D14: 1 | E14: 6 | F14: 4 | G14: 2 | H14: 454 | J14: =(D14-C14)/C14 -> -0.875 | K14: =(E14-D14)/D14 -> 5 | L14: =(F14-E14)/E14 -> -0.33333333 | M14: =(G14-F14)/F14 -> -0.5 | N14: =(H14-G14)/G14 -> 226 | P14: Trade Payables | Q14: 3257 | R14: 2785 | S14: 4095 | T14: 4385 | U14: 3785 | V14: 4411 | X14: =(R14-Q14)/Q14 -> -0.14491864 | Y14: =(S14-R14)/R14 -> 0.47037702 | Z14: =(T14-S14)/S14 -> 0.070818071 | AA14: =(U14-T14)/T14 -> -0.1368301 | AB14: =(V14-U14)/U14 -> 0.1653897
B15: Other income normal | C15: 1184 | D15: 787 | E15: 1109 | F15: 961 | G15: 925 | H15: 410 | J15: =(D15-C15)/C15 -> -0.33530405 | K15: =(E15-D15)/D15 -> 0.40914867 | L15: =(F15-E15)/E15 -> -0.13345356 | M15: =(G15-F15)/F15 -> -0.037460978 | N15: =(H15-G15)/G15 -> -0.55675676 | P15: Advance from Customers | Q15: 400 | R15: 0 | S15: 0 | T15: 0 | U15: 0 | V15: 0 | X15: =(R15-Q15)/Q15 -> -1
B16: Interest | C16: 192 | D16: 174 | E16: 163 | F16: 326 | G16: 392 | H16: 322 | J16: =(D16-C16)/C16 -> -0.09375 | K16: =(E16-D16)/D16 -> -0.063218391 | L16: =(F16-E16)/E16 -> 1 | M16: =(G16-F16)/F16 -> 0.20245399 | N16: =(H16-G16)/G16 -> -0.17857143 | P16: Other liability items | Q16: 7784 | R16: 8672 | S16: 10321 | T16: 10308 | U16: 9680 | V16: 10039 | X16: =(R16-Q16)/Q16 -> 0.11408016 | Y16: =(S16-R16)/R16 -> 0.19015221 | Z16: =(T16-S16)/S16 -> -0.0012595679 | AA16: =(U16-T16)/T16 -> -0.060923555 | AB16: =(V16-U16)/U16 -> 0.037086777
B17: Depreciation | C17: 1446 | D17: 1458 | E17: 1520 | F17: 1957 | G17: 1817 | H17: 1853 | J17: =(D17-C17)/C17 -> 0.0082987552 | K17: =(E17-D17)/D17 -> 0.042524005 | L17: =(F17-E17)/E17 -> 0.2875 | M17: =(G17-F17)/F17 -> -0.071538068 | N17: =(H17-G17)/G17 -> 0.019812878 | P17: Total Liabilities | Q17: 37318 | R17: 39602 | S17: 44416 | T17: 45827 | U17: 43149 | V17: 44267 | X17: =(R17-Q17)/Q17 -> 0.061203709 | Y17: =(S17-R17)/R17 -> 0.12155952 | Z17: =(T17-S17)/S17 -> 0.031767831 | AA17: =(U17-T17)/T17 -> -0.058437166 | AB17: =(V17-U17)/U17 -> 0.025910218
B18: Profit before tax | C18: 5058 | D18: 5953 | E18: 7452 | F18: 6446 | G18: 3224 | H18: 5653 | J18: =(D18-C18)/C18 -> 0.17694741 | K18: =(E18-D18)/D18 -> 0.25180581 | L18: =(F18-E18)/E18 -> -0.13499732 | M18: =(G18-F18)/F18 -> -0.49984487 | N18: =(H18-G18)/G18 -> 0.75341191 | P18: Fixed Assets | Q18: 8872 | R18: 9018 | S18: 14784 | T18: 14932 | U18: 13903 | V18: 13982 | X18: =(R18-Q18)/Q18 -> 0.016456267 | Y18: =(S18-R18)/R18 -> 0.63938789 | Z18: =(T18-S18)/S18 -> 0.010010823 | AA18: =(U18-T18)/T18 -> -0.068912403 | AB18: =(V18-U18)/U18 -> 0.0056822269
B19: Tax % | C19: 0.23 | D19: 0.27 | E19: 0.24 | F19: 0.25 | G19: 0.26 | H19: 0.25 | J19: =(D19-C19)/C19 -> 0.17391304 | K19: =(E19-D19)/D19 -> -0.11111111 | L19: =(F19-E19)/E19 -> 0.041666667 | M19: =(G19-F19)/F19 -> 0.04 | N19: =(H19-G19)/G19 -> -0.038461538 | P19: Land | Q19: 494 | R19: 441 | S19: 204 | T19: 206 | U19: 197 | V19: 210 | X19: =(R19-Q19)/Q19 -> -0.10728745 | Y19: =(S19-R19)/R19 -> -0.53741497 | Z19: =(T19-S19)/S19 -> 0.0098039216 | AA19: =(U19-T19)/T19 -> -0.04368932 | AB19: =(V19-U19)/U19 -> 0.065989848
B20: Net Profit | C20: 3897 | D20: 4353 | E20: 5630 | F20: 4857 | G20: 2397 | H20: 4253 | J20: =(D20-C20)/C20 -> 0.11701309 | K20: =(E20-D20)/D20 -> 0.2933609 | L20: =(F20-E20)/E20 -> -0.13730018 | M20: =(G20-F20)/F20 -> -0.50648548 | N20: =(H20-G20)/G20 -> 0.77430121 | P20: Building | Q20: 4138 | R20: 4282 | S20: 4687 | T20: 5251 | U20: 5119 | V20: 5718 | X20: =(R20-Q20)/Q20 -> 0.03479942 | Y20: =(S20-R20)/R20 -> 0.094581971 | Z20: =(T20-S20)/S20 -> 0.12033284 | AA20: =(U20-T20)/T20 -> -0.025138069 | AB20: =(V20-U20)/U20 -> 0.11701504
B21: Profit from Associates | C21: 0 | D21: 0 | E21: 0 | F21: 0 | G21: 0 | H21: 0 | P21: Plant Machinery | Q21: 2640 | R21: 2667 | S21: 2652 | T21: 2826 | U21: 2813 | V21: 2718
B22: Minority share | C22: 136 | D22: 75 | E22: -64 | F22: -26 | G22: -39 | H22: -2 | J22: =(D22-C22)/C22 -> -0.44852941 | K22: =(E22-D22)/D22 -> -1.8533333 | L22: =(F22-E22)/E22 -> -0.59375 | M22: =(G22-F22)/F22 -> 0.5 | N22: =(H22-G22)/G22 -> -0.94871795 | P22: Equipments | Q22: 267 | R22: 268 | S22: 286 | T22: 302 | U22: 319 | V22: 322 | X22: =(R22-Q22)/Q22 -> 0.0037453184 | Y22: =(S22-R22)/R22 -> 0.067164179 | Z22: =(T22-S22)/S22 -> 0.055944056 | AA22: =(U22-T22)/T22 -> 0.056291391 | AB22: =(V22-U22)/U22 -> 0.0094043887
B23: Exceptional items AT | C23: 6 | D23: 1 | E23: 5 | F23: 3 | G23: 2 | H23: 301 | J23: =(D23-C23)/C23 -> -0.83333333 | K23: =(E23-D23)/D23 -> 4 | L23: =(F23-E23)/E23 -> -0.4 | M23: =(G23-F23)/F23 -> -0.33333333 | N23: =(H23-G23)/G23 -> 149.5 | P23: Computers | Q23: 3581 | R23: 3415 | S23: 4259 | T23: 4972 | U23: 5346 | V23: 5520 | X23: =(R23-Q23)/Q23 -> -0.046355767 | Y23: =(S23-R23)/R23 -> 0.24714495 | Z23: =(T23-S23)/S23 -> 0.16741019 | AA23: =(U23-T23)/T23 -> 0.075221239 | AB23: =(V23-U23)/U23 -> 0.032547699
B24: Profit excl Excep | C24: 3891 | D24: 4352 | E24: 5625 | F24: 4854 | G24: 2395 | H24: 3952 | J24: =(D24-C24)/C24 -> 0.11847854 | K24: =(E24-D24)/D24 -> 0.29250919 | L24: =(F24-E24)/E24 -> -0.13706667 | M24: =(G24-F24)/F24 -> -0.5065925 | N24: =(H24-G24)/G24 -> 0.65010438 | P24: Furniture n fittings | Q24: 847 | R24: 849 | S24: 851 | T24: 884 | U24: 899 | V24: 853 | X24: =(R24-Q24)/Q24 -> 0.0023612751 | Y24: =(S24-R24)/R24 -> 0.0023557126 | Z24: =(T24-S24)/S24 -> 0.038777908 | AA24: =(U24-T24)/T24 -> 0.016968326 | AB24: =(V24-U24)/U24 -> -0.051167964
B25: Profit for PE | C25: 4027 | D25: 4427 | E25: 5561 | F25: 4828 | G25: 2356 | H25: 3950 | J25: =(D25-C25)/C25 -> 0.099329526 | K25: =(E25-D25)/D25 -> 0.25615541 | L25: =(F25-E25)/E25 -> -0.13181083 | M25: =(G25-F25)/F25 -> -0.51201326 | N25: =(H25-G25)/G25 -> 0.67657046 | P25: Vehicles | Q25: 88 | R25: 69 | S25: 67 | T25: 60 | U25: 64 | V25: 72 | X25: =(R25-Q25)/Q25 -> -0.21590909 | Y25: =(S25-R25)/R25 -> -0.028985507 | Z25: =(T25-S25)/S25 -> -0.10447761 | AA25: =(U25-T25)/T25 -> 0.066666667 | AB25: =(V25-U25)/U25 -> 0.125
B26: Profit for EPS | C26: 4033 | D26: 4428 | E26: 5566 | F26: 4831 | G26: 2358 | H26: 4252 | J26: =(D26-C26)/C26 -> 0.097941979 | K26: =(E26-D26)/D26 -> 0.2570009 | L26: =(F26-E26)/E26 -> -0.13205174 | M26: =(G26-F26)/F26 -> -0.5119023 | N26: =(H26-G26)/G26 -> 0.80322307 | P26: Intangible Assets | Q26: 4776 | R26: 5426 | S26: 9044 | T26: 9369 | U26: 9257 | V26: 9357 | X26: =(R26-Q26)/Q26 -> 0.13609715 | Y26: =(S26-R26)/R26 -> 0.66678953 | Z26: =(T26-S26)/S26 -> 0.035935427 | AA26: =(U26-T26)/T26 -> -0.011954317 | AB26: =(V26-U26)/U26 -> 0.010802636
B27: Profit Growth % | C27: -0.06 | D27: 0.1 | E27: 0.26 | F27: -0.13 | G27: -0.51 | H27: 0.68 | J27: =(D27-C27)/C27 -> -2.6666667 | K27: =(E27-D27)/D27 -> 1.6 | L27: =(F27-E27)/E27 -> -1.5 | M27: =(G27-F27)/F27 -> 2.9230769 | N27: =(H27-G27)/G27 -> -2.3333333 | P27: Other fixed assets | Q27: 1344 | R27: 1524 | S27: 3920 | T27: 4214 | U27: 4313 | V27: 4350 | X27: =(R27-Q27)/Q27 -> 0.13392857 | Y27: =(S27-R27)/R27 -> 1.5721785 | Z27: =(T27-S27)/S27 -> 0.075 | AA27: =(U27-T27)/T27 -> 0.023493118 | AB27: =(V27-U27)/U27 -> 0.0085787155
B28: EPS in Rs | C28: 41.76 | D28: 45.73 | E28: 57.27 | F28: 49.6 | G28: 24.14 | H28: 43.43 | J28: =(D28-C28)/C28 -> 0.09506705 | K28: =(E28-D28)/D28 -> 0.25235075 | L28: =(F28-E28)/E28 -> -0.13392701 | M28: =(G28-F28)/F28 -> -0.51330645 | N28: =(H28-G28)/G28 -> 0.79908865 | P28: Gross Block | Q28: 18177 | R28: 18941 | S28: 25971 | T28: 28085 | U28: 28327 | V28: 29120 | X28: =(R28-Q28)/Q28 -> 0.042031138 | Y28: =(S28-R28)/R28 -> 0.37115253 | Z28: =(T28-S28)/S28 -> 0.081398483 | AA28: =(U28-T28)/T28 -> 0.0086166993 | AB28: =(V28-U28)/U28 -> 0.027994493
B29: Dividend Payout % | C29: 0.32 | D29: 0.89 | E29: 0.47 | F29: 0.91 | G29: 1.5 | H29: 0.94 | J29: =(D29-C29)/C29 -> 1.78125 | K29: =(E29-D29)/D29 -> -0.47191011 | L29: =(F29-E29)/E29 -> 0.93617021 | M29: =(G29-F29)/F29 -> 0.64835165 | N29: =(H29-G29)/G29 -> -0.37333333 | P29: Accumulated Depreciation | Q29: 9305 | R29: 9923 | S29: 11188 | T29: 13154 | U29: 14424 | V29: 15139 | X29: =(R29-Q29)/Q29 -> 0.066415905 | Y29: =(S29-R29)/R29 -> 0.12748161 | Z29: =(T29-S29)/S29 -> 0.17572399 | AA29: =(U29-T29)/T29 -> 0.096548578 | AB29: =(V29-U29)/U29 -> 0.049570161
P30: CWIP | Q30: 50 | R30: 118 | S30: 165 | T30: 120 | U30: 133 | V30: 21 | X30: =(R30-Q30)/Q30 -> 1.36 | Y30: =(S30-R30)/R30 -> 0.39830508 | Z30: =(T30-S30)/S30 -> -0.27272727 | AA30: =(U30-T30)/T30 -> 0.10833333 | AB30: =(V30-U30)/U30 -> -0.84210526
P31: Investments | Q31: 5848 | R31: 10238 | S31: 4884 | T31: 3388 | U31: 3238 | V31: 3182 | X31: =(R31-Q31)/Q31 -> 0.75068399 | Y31: =(S31-R31)/R31 -> -0.5229537 | Z31: =(T31-S31)/S31 -> -0.30630631 | AA31: =(U31-T31)/T31 -> -0.044273908 | AB31: =(V31-U31)/U31 -> -0.017294626
P32: Other Assets | Q32: 22548 | R32: 20228 | S32: 24583 | T32: 27388 | U32: 25875 | V32: 27082 | X32: =(R32-Q32)/Q32 -> -0.10289161 | Y32: =(S32-R32)/R32 -> 0.21529563 | Z32: =(T32-S32)/S32 -> 0.11410324 | AA32: =(U32-T32)/T32 -> -0.055243172 | AB32: =(V32-U32)/U32 -> 0.046647343
P33: Inventories | Q33: 36 | R33: 24 | S33: 40 | T33: 24 | U33: 38 | V33: 39 | X33: =(R33-Q33)/Q33 -> -0.33333333 | Y33: =(S33-R33)/R33 -> 0.66666667 | Z33: =(T33-S33)/S33 -> -0.4 | AA33: =(U33-T33)/T33 -> 0.58333333 | AB33: =(V33-U33)/U33 -> 0.026315789
P34: Trade receivables | Q34: 7577 | R34: 6473 | S34: 11933 | T34: 12882 | U34: 11401 | V34: 11547 | X34: =(R34-Q34)/Q34 -> -0.1457041 | Y34: =(S34-R34)/R34 -> 0.84350378 | Z34: =(T34-S34)/S34 -> 0.079527361 | AA34: =(U34-T34)/T34 -> -0.11496662 | AB34: =(V34-U34)/U34 -> 0.012805894
P35: Receivables over 6m | Q35: 0 | R35: 0 | S35: 0 | T35: 1296 | U35: 1195 | V35: 1506 | AA35: =(U35-T35)/T35 -> -0.077932099 | AB35: =(V35-U35)/U35 -> 0.26025105
P36: Receivables under 6m | Q36: 8304 | R36: 7164 | S36: 12606 | T36: 12360 | U36: 11140 | V36: 11198 | X36: =(R36-Q36)/Q36 -> -0.13728324 | Y36: =(S36-R36)/R36 -> 0.75963149 | Z36: =(T36-S36)/S36 -> -0.019514517 | AA36: =(U36-T36)/T36 -> -0.098705502 | AB36: =(V36-U36)/U36 -> 0.0052064632
P37: Prov for Doubtful | Q37: -726 | R37: -692 | S37: -673 | T37: -775 | U37: -935 | V37: -1157 | X37: =(R37-Q37)/Q37 -> -0.046831956 | Y37: =(S37-R37)/R37 -> -0.027456647 | Z37: =(T37-S37)/S37 -> 0.15156018 | AA37: =(U37-T37)/T37 -> 0.20645161 | AB37: =(V37-U37)/U37 -> 0.23743316
P38: Cash Equivalents | Q38: 3148 | R38: 2835 | S38: 3974 | T38: 4255 | U38: 4736 | V38: 4542 | X38: =(R38-Q38)/Q38 -> -0.099428208 | Y38: =(S38-R38)/R38 -> 0.40176367 | Z38: =(T38-S38)/S38 -> 0.070709612 | AA38: =(U38-T38)/T38 -> 0.11304348 | AB38: =(V38-U38)/U38 -> -0.040962838
P39: Loans n Advances | Q39: 570 | R39: 801 | S39: 1219 | T39: 1128 | U39: 1202 | V39: 1220 | X39: =(R39-Q39)/Q39 -> 0.40526316 | Y39: =(S39-R39)/R39 -> 0.52184769 | Z39: =(T39-S39)/S39 -> -0.074651354 | AA39: =(U39-T39)/T39 -> 0.065602837 | AB39: =(V39-U39)/U39 -> 0.014975042
P40: Other asset items | Q40: 11217 | R40: 10094 | S40: 7416 | T40: 9100 | U40: 8499 | V40: 9734 | X40: =(R40-Q40)/Q40 -> -0.1001159 | Y40: =(S40-R40)/R40 -> -0.26530612 | Z40: =(T40-S40)/S40 -> 0.22707659 | AA40: =(U40-T40)/T40 -> -0.066043956 | AB40: =(V40-U40)/U40 -> 0.14531121
P41: Total Assets | Q41: 37318 | R41: 39602 | S41: 44416 | T41: 45827 | U41: 43149 | V41: 44267 | X41: =(R41-Q41)/Q41 -> 0.061203709 | Y41: =(S41-R41)/R41 -> 0.12155952 | Z41: =(T41-S41)/S41 -> 0.031767831 | AA41: =(U41-T41)/T41 -> -0.058437166 | AB41: =(V41-U41)/U41 -> 0.025910218

Sheet Beta
A1: Tech Mahindra | E1: Nifty | I1: Beta Calculation
A2: Date | B2: Close | C2: Return | E2: Date | F2: Close | G2: Return
A3: 43922 | B3: 511.2 | E3: 43922 | F3: 8253.7998 | I3: Srl. No. | J3: Particular | K3: Value | L3: Formula
A4: 43924 | B4: 520.9 | C4: =(B4-B3)/B3 -> 0.018974961 | E4: 43924 | F4: 8083.7998 | G4: =(F4-F3)/F3 -> -0.020596574 | I4: 1 | J4: Beta | K4: =SLOPE(C4:C1484,G4:G1484) -> 0.88898841 | L4: =+_xlfn.FORMULATEXT(K4) -> =SLOPE(C4:C1484,G4:G1484)
A5: 43928 | B5: 549.85 | C5: =(B5-B4)/B4 -> 0.055576886 | E5: 43928 | F5: 8792.2002 | G5: =(F5-F4)/F4 -> 0.087632105
A6: 43929 | B6: 558.9 | C6: =(B6-B5)/B5 -> 0.016459034 | E6: 43929 | F6: 8748.75 | G6: =(F6-F5)/F5 -> -0.0049419024 | I6: 2 | J6: Beta | K6: =_xlfn.COVARIANCE.S(C4:C1484,G4:G1484)/_xlfn.VAR.S(G4:G1484) -> 0.88898841 | L6: =+_xlfn.FORMULATEXT(K6) -> =COVARIANCE.S(C4:C1484,G4:G1484)/VAR.S(G4:G1484)
A7: 43930 | B7: 545.25 | C7: =(B7-B6)/B6 -> -0.024422974 | E7: 43930 | F7: 9111.9004 | G7: =(F7-F6)/F6 -> 0.041508832
A8: 43934 | B8: 526.85 | C8: =(B8-B7)/B7 -> -0.033745988 | E8: 43934 | F8: 8993.8496 | G8: =(F8-F7)/F7 -> -0.012955671 | I8: 3 | J8: SUMMARY OUTPUT
A9: 43936 | B9: 538.65 | C9: =(B9-B8)/B8 -> 0.022397267 | E9: 43936 | F9: 8925.2998 | G9: =(F9-F8)/F8 -> -0.0076218536 | J9: Regression Statistics
A10: 43937 | B10: 517.65 | C10: =(B10-B9)/B9 -> -0.038986355 | E10: 43937 | F10: 8992.7998 | G10: =(F10-F9)/F9 -> 0.0075627712 | J10: Multiple R | K10: 0.48871498
A11: 43938 | B11: 509.85 | C11: =(B11-B10)/B10 -> -0.015068096 | E11: 43938 | F11: 9266.75 | G11: =(F11-F10)/F10 -> 0.030463282 | J11: R Square | K11: 0.23884233
A12: 43941 | B12: 524.85 | C12: =(B12-B11)/B11 -> 0.029420418 | E12: 43941 | F12: 9261.8496 | G12: =(F12-F11)/F11 -> -0.00052881438 | J12: Adjusted R Square | K12: 0.23832769
A13: 43942 | B13: 512.95 | C13: =(B13-B12)/B12 -> -0.022673145 | E13: 43942 | F13: 8981.4502 | G13: =(F13-F12)/F12 -> -0.030274667 | J13: Standard Error | K13: 0.015554075
A14: 43943 | B14: 518.3 | C14: =(B14-B13)/B13 -> 0.010429866 | E14: 43943 | F14: 9187.2998 | G14: =(F14-F13)/F13 -> 0.022919418 | J14: Observations | K14: 1481
A15: 43944 | B15: 523.7 | C15: =(B15-B14)/B14 -> 0.010418676 | E15: 43944 | F15: 9313.9004 | G15: =(F15-F14)/F14 -> 0.013779956
A16: 43945 | B16: 503.45 | C16: =(B16-B15)/B15 -> -0.038667176 | E16: 43945 | F16: 9154.4004 | G16: =(F16-F15)/F15 -> -0.017124942 | J16: ANOVA
A17: 43948 | B17: 511.7 | C17: =(B17-B16)/B16 -> 0.01638693 | E17: 43948 | F17: 9282.2998 | G17: =(F17-F16)/F16 -> 0.013971359 | K17: df | L17: SS | M17: MS | N17: F | O17: Significance F
A18: 43949 | B18: 520.4 | C18: =(B18-B17)/B17 -> 0.01700215 | E18: 43949 | F18: 9380.9004 | G18: =(F18-F17)/F17 -> 0.010622431 | J18: Regression | K18: 1 | L18: 0.11227763 | M18: 0.11227763 | N18: 464.09282 | O18: 9.4925878e-90
A19: 43950 | B19: 528.7 | C19: =(B19-B18)/B18 -> 0.01594927 | E19: 43950 | F19: 9553.3496 | G19: =(F19-F18)/F18 -> 0.018383014 | J19: Residual | K19: 1479 | L19: 0.35781337 | M19: 0.00024192925
A20: 43951 | B20: 546.25 | C20: =(B20-B19)/B19 -> 0.033194628 | E20: 43951 | F20: 9859.9004 | G20: =(F20-F19)/F19 -> 0.032088303 | J20: Total | K20: 1480 | L20: 0.47009099
A21: 43955 | B21: 502.45 | C21: =(B21-B20)/B20 -> -0.080183066 | E21: 43955 | F21: 9293.5 | G21: =(F21-F20)/F20 -> -0.057444839
A22: 43956 | B22: 499.95 | C22: =(B22-B21)/B21 -> -0.0049756195 | E22: 43956 | F22: 9205.5996 | G22: =(F22-F21)/F21 -> -0.0094582655 | K22: Coefficients | L22: Standard Error | M22: t Stat | N22: P-value | O22: Lower 95% | P22: Upper 95% | Q22: Lower 95.0% | R22: Upper 95.0%
A23: 43957 | B23: 506.85 | C23: =(B23-B22)/B22 -> 0.01380138 | E23: 43957 | F23: 9270.9004 | G23: =(F23-F22)/F22 -> 0.0070935935 | J23: Intercept | K23: 0.00019116936 | L23: 0.0004052637 | M23: 0.47171598 | N23: 0.63719911 | O23: -0.00060378345 | P23: 0.00098612217 | Q23: -0.00060378345 | R23: 0.00098612217
A24: 43958 | B24: 516.35 | C24: =(B24-B23)/B23 -> 0.018743218 | E24: 43958 | F24: 9199.0498 | G24: =(F24-F23)/F23 -> -0.0077501195 | J24: X Variable 1 | K24: 0.88898841 | L24: 0.041266124 | M24: 21.542814 | N24: 9.4925878e-90 | O24: 0.80804206 | P24: 0.96993477 | Q24: 0.80804206 | R24: 0.96993477
A25: 43959 | B25: 536.2 | C25: =(B25-B24)/B24 -> 0.038442917 | E25: 43959 | F25: 9251.5 | G25: =(F25-F24)/F24 -> 0.0057016971
A26: 43962 | B26: 530.2 | C26: =(B26-B25)/B25 -> -0.011189855 | E26: 43962 | F26: 9239.2002 | G26: =(F26-F25)/F25 -> -0.001329493
A27: 43963 | B27: 533.25 | C27: =(B27-B26)/B26 -> 0.0057525462 | E27: 43963 | F27: 9196.5498 | G27: =(F27-F26)/F26 -> -0.0046162427
A28: 43964 | B28: 544.75 | C28: =(B28-B27)/B27 -> 0.02156587 | E28: 43964 | F28: 9383.5498 | G28: =(F28-F27)/F27 -> 0.020333713
A29: 43965 | B29: 515.7 | C29: =(B29-B28)/B28 -> -0.053327214 | E29: 43965 | F29: 9142.75 | G29: =(F29-F28)/F28 -> -0.025661909
A30: 43966 | B30: 510.55 | C30: =(B30-B29)/B29 -> -0.0099864262 | E30: 43966 | F30: 9136.8496 | G30: =(F30-F29)/F29 -> -0.00064536279
A31: 43969 | B31: 504.05 | C31: =(B31-B30)/B30 -> -0.012731368 | E31: 43969 | F31: 8823.25 | G31: =(F31-F30)/F30 -> -0.03432251
A32: 43970 | B32: 512.6 | C32: =(B32-B31)/B31 -> 0.016962603 | E32: 43970 | F32: 8879.0996 | G32: =(F32-F31)/F31 -> 0.0063298228
A33: 43971 | B33: 519.2 | C33: =(B33-B32)/B32 -> 0.012875536 | E33: 43971 | F33: 9066.5498 | G33: =(F33-F32)/F32 -> 0.021111397
A34: 43972 | B34: 520.05 | C34: =(B34-B33)/B33 -> 0.0016371341 | E34: 43972 | F34: 9106.25 | G34: =(F34-F33)/F33 -> 0.0043787545
A35: 43973 | B35: 529.65 | C35: =(B35-B34)/B34 -> 0.018459763 | E35: 43973 | F35: 9039.25 | G35: =(F35-F34)/F34 -> -0.0073575841
A36: 43977 | B36: 520.45 | C36: =(B36-B35)/B35 -> -0.017369961 | E36: 43977 | F36: 9029.0498 | G36: =(F36-F35)/F35 -> -0.0011284338
... A1484: 46111 | B1484: 1384 | C1484: =(B1484-B1483)/B1483 -> -0.0054613395 | E1484: 46111 | F1484: 22331.4 | G1484: =(F1484-F1483)/F1483 -> -0.021393856

Sheet WACC
B1: Tech Mahindra Ltd. — Weighted Average Cost of Capital (WACC)
B3: Capital Structure (FY2025 Balance Sheet — Market Value Weights)
B4: Particulars | C4: Book Value (₹ Cr) | D4: Market Value (₹ Cr) | E4: Weight
B5: Equity (Market Cap) | C5: =Assumptions!G34 -> 27361 | D5: 140076 | E5: =D5/(D5+D6) -> 0.98574957
B6: Debt (Book Value of Borrowings) | C6: =Assumptions!G35 -> 2025 | D6: 2025 | E6: =D6/(D5+D6) -> 0.014250428
B7: Total Capital | C7: =C5+C6 -> 29386 | D7: =D5+D6 -> 142101 | E7: =E5+E6 -> 1
B9: Cost of Equity (Capital Asset Pricing Model — CAPM)
B10: Particulars | C10: Value
B11: Risk-Free Rate (Rf) | C11: 0.067
B12: Equity Risk Premium (ERP) | C12: 0.0744
B13: Beta (Beta) — Regressed (5-yr daily vs Nifty 50) | C13: =Beta!K4 -> 0.88898841
B14: Debt/Equity ratio (D/E) | C14: =D6/D5 -> 0.014456438
B15: Beta × ERP | C15: =C13*C12 -> 0.066140738
B16: Cost of Equity [Ke = Rf + β × ERP] | C16: =C11+C13*C12 -> 0.13314074
B18: Cost of Debt (Post-Tax)
B19: Particulars | C19: Value
B20: Total Interest Expense (FY2025) | C20: ='Consolidated FS'!H16 -> 322
B21: Average Total Borrowings (FY2024-FY2025) | C21: =('Consolidated FS'!U7+'Consolidated FS'!V7)/2 -> 2281
B22: Pre-Tax Cost of Debt [Kd = Interest / Avg Debt] | C22: =C20/C21 -> 0.14116616
B23: Marginal Tax Rate | C23: 0.25
B24: Post-Tax Cost of Debt [Kd(1-t)] | C24: =C22*(1-C23) -> 0.10587462
B26: WACC Calculation [WACC = Ke × We + Kd(1-t) × Wd]
B27: Component | C27: Cost (%) | D27: Weight (%) | E27: Contribution (%)
B28: Equity | C28: =C16 -> 0.13314074 | D28: =E5 -> 0.98574957 | E28: =C28*D28 -> 0.13124343
B29: Debt | C29: =C24 -> 0.10587462 | D29: =E6 -> 0.014250428 | E29: =C29*D29 -> 0.0015087585
B30: WACC | E30: =E28+E29 -> 0.13275218

Sheet Assumptions
B2: Particulars | C2: 2021 | D2: 2022 | E2: 2023 | F2: 2024 | G2: 2025
B3: Revenur from Operations | C3: ='Consolidated FS'!D5 -> 37855 | D3: ='Consolidated FS'!E5 -> 44646 | E3: ='Consolidated FS'!F5 -> 53290 | F3: ='Consolidated FS'!G5 -> 51996 | G3: ='Consolidated FS'!H5 -> 52988
B4: Revenue Growth | D4: =(D3-C3)/C3 -> 0.17939506 | E4: =(E3-D3)/D3 -> 0.19361197 | F4: =(F3-E3)/E3 -> -0.024282229 | G4: =(G3-F3)/F3 -> 0.019078391
B5: Less:Material Cost | C5: ='Consolidated FS'!D8*'Consolidated FS'!D5 -> 8706.65 | D5: ='Consolidated FS'!E8*'Consolidated FS'!E5 -> 11607.96 | E5: ='Consolidated FS'!F8*'Consolidated FS'!F5 -> 13855.4 | F5: ='Consolidated FS'!G8*'Consolidated FS'!G5 -> 12999 | G5: ='Consolidated FS'!H8*'Consolidated FS'!H5 -> 12187.24
B6: Less:Employee Cost | C6: ='Consolidated FS'!D9*'Consolidated FS'!D5 -> 19306.05 | D6: ='Consolidated FS'!E9*'Consolidated FS'!E5 -> 22323 | E6: ='Consolidated FS'!F9*'Consolidated FS'!F5 -> 27710.8 | F6: ='Consolidated FS'!G9*'Consolidated FS'!G5 -> 29117.76 | G6: ='Consolidated FS'!H9*'Consolidated FS'!H5 -> 29673.28
B7: Less: Other Expense | C7: ='Consolidated FS'!D10*'Consolidated FS'!D5 -> 3028.4 | D7: ='Consolidated FS'!E10*'Consolidated FS'!E5 -> 3125.22 | E7: ='Consolidated FS'!F10*'Consolidated FS'!F5 -> 4263.2 | F7: ='Consolidated FS'!G10*'Consolidated FS'!G5 -> 5199.6 | G7: ='Consolidated FS'!H10*'Consolidated FS'!H5 -> 4239.04
B8: Total Expense | C8: =SUM(C5:C7) -> 31041.1 | D8: =SUM(D5:D7) -> 37056.18 | E8: =SUM(E5:E7) -> 45829.4 | F8: =SUM(F5:F7) -> 47316.36 | G8: =SUM(G5:G7) -> 46099.56
B9: EBITDA | C9: =C3-C8 -> 6813.9 | D9: =D3-D8 -> 7589.82 | E9: =E3-E8 -> 7460.6 | F9: =F3-F8 -> 4679.64 | G9: =G3-G8 -> 6888.44
B10: Less: Depreciation and Amortization | C10: ='Consolidated FS'!D17 -> 1458 | D10: ='Consolidated FS'!E17 -> 1520 | E10: ='Consolidated FS'!F17 -> 1957 | F10: ='Consolidated FS'!G17 -> 1817 | G10: ='Consolidated FS'!H17 -> 1853
B11: EBIT | C11: =C9-C10 -> 5355.9 | D11: =D9-D10 -> 6069.82 | E11: =E9-E10 -> 5503.6 | F11: =F9-F10 -> 2862.64 | G11: =G9-G10 -> 5035.44
B12: Add: Non Operating Income/Other Income | C12: ='Consolidated FS'!D15 -> 787 | D12: ='Consolidated FS'!E15 -> 1109 | E12: ='Consolidated FS'!F15 -> 961 | F12: ='Consolidated FS'!G15 -> 925 | G12: ='Consolidated FS'!H15 -> 410
B13: Less:Interest Expense | C13: ='Consolidated FS'!D16 -> 174 | D13: ='Consolidated FS'!E16 -> 163 | E13: ='Consolidated FS'!F16 -> 326 | F13: ='Consolidated FS'!G16 -> 392 | G13: ='Consolidated FS'!H16 -> 322
B14: EBT | C14: =C11+C12-C13 -> 5968.9 | D14: =D11+D12-D13 -> 7015.82 | E14: =E11+E12-E13 -> 6138.6 | F14: =F11+F12-F13 -> 3395.64 | G14: =G11+G12-G13 -> 5123.44
B15: Less: Tax | C15: ='Consolidated FS'!D19*'Consolidated FS'!D18 -> 1607.31 | D15: ='Consolidated FS'!E19*'Consolidated FS'!E18 -> 1788.48 | E15: ='Consolidated FS'!F19*'Consolidated FS'!F18 -> 1611.5 | F15: ='Consolidated FS'!G19*'Consolidated FS'!G18 -> 838.24 | G15: ='Consolidated FS'!H19*'Consolidated FS'!H18 -> 1413.25
B16: Less:Non Controlling Interest/Minority Interest | C16: ='Consolidated FS'!D22 -> 75 | D16: ='Consolidated FS'!E22 -> -64 | E16: ='Consolidated FS'!F22 -> -26 | F16: ='Consolidated FS'!G22 -> -39 | G16: ='Consolidated FS'!H22 -> -2
B17: PAT | C17: =C14-C15-C16 -> 4286.59 | D17: =D14-D15-D16 -> 5291.34 | E17: =E14-E15-E16 -> 4553.1 | F17: =F14-F15-F16 -> 2596.4 | G17: =G14-G15-G16 -> 3712.19
B19: Historical Growth
B20: Average Growth | C20: =AVERAGE(D4:G4) -> 0.091950798
B21: CAGR | C21: =(G3/C3)^(1/4)-1 -> 0.087711122 | D21: =(G3/C3)^(1/4)-1 -> 0.087711122
B22: Margin Analysis
B23: EBITDA Margin | C23: =C9/C3 -> 0.18 | D23: =D9/D3 -> 0.17 | E23: =E9/E3 -> 0.14 | F23: =F9/F3 -> 0.09 | G23: =G9/G3 -> 0.13
B24: EBIT Margin | C24: =C11/C3 -> 0.14148461 | D24: =D11/D3 -> 0.1359544 | E24: =E11/E3 -> 0.10327641 | F24: =F11/F3 -> 0.055055004 | G24: =G11/G3 -> 0.095029818
B25: EBT Margin | C25: =C14/C3 -> 0.15767798 | D25: =D14/D3 -> 0.15714331 | E25: =E14/E3 -> 0.11519234 | F25: =F14/F3 -> 0.065305793 | G25: =G14/G3 -> 0.096690571
B26: PAT Margin | C26: =C17/C3 -> 0.11323709 | D26: =D17/D3 -> 0.11851767 | E26: =E17/E3 -> 0.085440045 | F26: =F17/F3 -> 0.04993461 | G26: =G17/G3 -> 0.070057183
B28: Tax Rate
B29: Effective Tax Rate | C29: =C15/C14 -> 0.26928077 | D29: =D15/D14 -> 0.25492102 | E29: =E15/E14 -> 0.26251914 | F29: =F15/F14 -> 0.24685774 | G29: =G15/G14 -> 0.27584006
B30: Marginal Tax Rate | C30: 0.25 | D30: 0.25 | E30: 0.25 | F30: 0.25 | G30: 0.25
B32: Return on Capital
B33: EBIT(1-t) | C33: =C11*(1-C30) -> 4016.925 | D33: =D11*(1-D30) -> 4552.365 | E33: =E11*(1-E30) -> 4127.7 | F33: =F11*(1-F30) -> 2146.98 | G33: =G11*(1-G30) -> 3776.58
B34: Book Equity | C34: ='Consolidated FS'!R5+'Consolidated FS'!R6 -> 24865 | D34: ='Consolidated FS'!S5+'Consolidated FS'!S6 -> 26886 | E34: ='Consolidated FS'!T5+'Consolidated FS'!T6 -> 27924 | F34: ='Consolidated FS'!U5+'Consolidated FS'!U6 -> 26669 | G34: ='Consolidated FS'!V5+'Consolidated FS'!V6 -> 27361
B35: Book Debt | C35: ='Consolidated FS'!R7 -> 2901 | D35: ='Consolidated FS'!S7 -> 2618 | E35: ='Consolidated FS'!T7 -> 2740 | F35: ='Consolidated FS'!U7 -> 2537 | G35: ='Consolidated FS'!V7 -> 2025
B36: Cash and Cash Equivalents | C36: ='Consolidated FS'!R38 -> 2835 | D36: ='Consolidated FS'!S38 -> 3974 | E36: ='Consolidated FS'!T38 -> 4255 | F36: ='Consolidated FS'!U38 -> 4736 | G36: ='Consolidated FS'!V38 -> 4542
B37: Capital Employed | C37: =C34+C35+C36 -> 30601 | D37: =D34+D35+D36 -> 33478 | E37: =E34+E35+E36 -> 34919 | F37: =F34+F35+F36 -> 33942 | G37: =G34+G35+G36 -> 33928
B39: Pre Tax Return on Capital | C39: =C11/C37 -> 0.17502369 | D39: =D11/D37 -> 0.18130772 | E39: =E11/E37 -> 0.15761047 | F39: =F11/F37 -> 0.084339167 | G39: =G11/G37 -> 0.14841547
B40: Post Tax Return on Capital | C40: =C33/C37 -> 0.13126777 | D40: =D33/D37 -> 0.13598079 | E40: =E33/E37 -> 0.11820785 | F40: =F33/F37 -> 0.063254375 | G40: =G33/G37 -> 0.1113116
B42: Growth Summary
B43: Average Revenue Growth | C43: =AVERAGE(D4:G4) -> 0.091950798
B44: Revenue CAGR | C44: =(G3/C3)^(1/4)-1 -> 0.087711122
B46: Growth in EBIT | C46: =FCFF!C13*G40 -> 0.034078657

Sheet Ratios
B2: Ratios
B3: Particulars | C3: 2021 | D3: 2022 | E3: 2023 | F3: 2024 | G3: 2025 | H3: Trend | I3: Mean | J3: Median
B4: Growth Ratios
B5: Sales Growth | D5: =(Assumptions!D3-Assumptions!C3)/ABS(Assumptions!C3) -> 0.17939506 | E5: =(Assumptions!E3-Assumptions!D3)/ABS(Assumptions!D3) -> 0.19361197 | F5: =(Assumptions!F3-Assumptions!E3)/ABS(Assumptions!E3) -> -0.024282229 | G5: =(Assumptions!G3-Assumptions!F3)/ABS(Assumptions!F3) -> 0.019078391 | I5: =AVERAGE(D5:G5) -> 0.091950798 | J5: =MEDIAN(D5:G5) -> 0.099236725
B6: EBITDA Growth | D6: =(Assumptions!D9-Assumptions!C9)/ABS(Assumptions!C9) -> 0.11387311 | E6: =(Assumptions!E9-Assumptions!D9)/ABS(Assumptions!D9) -> -0.017025437 | F6: =(Assumptions!F9-Assumptions!E9)/ABS(Assumptions!E9) -> -0.37275286 | G6: =(Assumptions!G9-Assumptions!F9)/ABS(Assumptions!F9) -> 0.47200212 | I6: =AVERAGE(D6:G6) -> 0.049024233 | J6: =MEDIAN(D6:G6) -> 0.048423838
B7: EBIT Growth | D7: =(Assumptions!D11-Assumptions!C11)/ABS(Assumptions!C11) -> 0.13329599 | E7: =(Assumptions!E11-Assumptions!D11)/ABS(Assumptions!D11) -> -0.09328448 | F7: =(Assumptions!F11-Assumptions!E11)/ABS(Assumptions!E11) -> -0.47986045 | G7: =(Assumptions!G11-Assumptions!F11)/ABS(Assumptions!F11) -> 0.75901965 | I7: =AVERAGE(D7:G7) -> 0.079792676 | J7: =MEDIAN(D7:G7) -> 0.020005756
B8: Net Profit Growth | D8: =(Assumptions!D17-Assumptions!C17)/ABS(Assumptions!C17) -> 0.23439377 | E8: =(Assumptions!E17-Assumptions!D17)/ABS(Assumptions!D17) -> -0.13951853 | F8: =(Assumptions!F17-Assumptions!E17)/ABS(Assumptions!E17) -> -0.42975116 | G8: =(Assumptions!G17-Assumptions!F17)/ABS(Assumptions!F17) -> 0.42974503 | I8: =AVERAGE(D8:G8) -> 0.023717278 | J8: =MEDIAN(D8:G8) -> 0.047437619
B10: Margin Ratios
B11: EBITDA Margin | C11: =Assumptions!C9/Assumptions!C3 -> 0.18 | D11: =Assumptions!D9/Assumptions!D3 -> 0.17 | E11: =Assumptions!E9/Assumptions!E3 -> 0.14 | F11: =Assumptions!F9/Assumptions!F3 -> 0.09 | G11: =Assumptions!G9/Assumptions!G3 -> 0.13 | I11: =AVERAGE(C11:G11) -> 0.142 | J11: =MEDIAN(C11:G11) -> 0.14
B12: EBIT Margin | C12: =Assumptions!C11/Assumptions!C3 -> 0.14148461 | D12: =Assumptions!D11/Assumptions!D3 -> 0.1359544 | E12: =Assumptions!E11/Assumptions!E3 -> 0.10327641 | F12: =Assumptions!F11/Assumptions!F3 -> 0.055055004 | G12: =Assumptions!G11/Assumptions!G3 -> 0.095029818 | I12: =AVERAGE(C12:G12) -> 0.10616005 | J12: =MEDIAN(C12:G12) -> 0.10327641
B13: EBT Margin | C13: =Assumptions!C14/Assumptions!C3 -> 0.15767798 | D13: =Assumptions!D14/Assumptions!D3 -> 0.15714331 | E13: =Assumptions!E14/Assumptions!E3 -> 0.11519234 | F13: =Assumptions!F14/Assumptions!F3 -> 0.065305793 | G13: =Assumptions!G14/Assumptions!G3 -> 0.096690571 | I13: =AVERAGE(C13:G13) -> 0.118402 | J13: =MEDIAN(C13:G13) -> 0.11519234
B14: PAT Margin | C14: =Assumptions!C17/Assumptions!C3 -> 0.11323709 | D14: =Assumptions!D17/Assumptions!D3 -> 0.11851767 | E14: =Assumptions!E17/Assumptions!E3 -> 0.085440045 | F14: =Assumptions!F17/Assumptions!F3 -> 0.04993461 | G14: =Assumptions!G17/Assumptions!G3 -> 0.070057183 | I14: =AVERAGE(C14:G14) -> 0.08743732 | J14: =MEDIAN(C14:G14) -> 0.085440045
B16: Return Ratios
B17: Pre-Tax ROIC | C17: =Assumptions!C39 -> 0.17502369 | D17: =Assumptions!D39 -> 0.18130772 | E17: =Assumptions!E39 -> 0.15761047 | F17: =Assumptions!F39 -> 0.084339167 | G17: =Assumptions!G39 -> 0.14841547 | I17: =AVERAGE(C17:G17) -> 0.1493393 | J17: =MEDIAN(C17:G17) -> 0.15761047
B18: Post-Tax ROIC | C18: =Assumptions!C40 -> 0.13126777 | D18: =Assumptions!D40 -> 0.13598079 | E18: =Assumptions!E40 -> 0.11820785 | F18: =Assumptions!F40 -> 0.063254375 | G18: =Assumptions!G40 -> 0.1113116 | I18: =AVERAGE(C18:G18) -> 0.11200448 | J18: =MEDIAN(C18:G18) -> 0.11820785
B20: Other Ratios
B21: Dividend Growth | D21: =('Consolidated FS'!E29-'Consolidated FS'!D29)/ABS('Consolidated FS'!D29) -> -0.47191011 | E21: =('Consolidated FS'!F29-'Consolidated FS'!E29)/ABS('Consolidated FS'!E29) -> 0.93617021 | F21: =('Consolidated FS'!G29-'Consolidated FS'!F29)/ABS('Consolidated FS'!F29) -> 0.64835165 | G21: =('Consolidated FS'!H29-'Consolidated FS'!G29)/ABS('Consolidated FS'!G29) -> -0.37333333 | I21: =AVERAGE(D21:G21) -> 0.1848196 | J21: =MEDIAN(D21:G21) -> 0.13750916
B22: EPS Growth | D22: =('Consolidated FS'!E28-'Consolidated FS'!D28)/ABS('Consolidated FS'!D28) -> 0.25235075 | E22: =('Consolidated FS'!F28-'Consolidated FS'!E28)/ABS('Consolidated FS'!E28) -> -0.13392701 | F22: =('Consolidated FS'!G28-'Consolidated FS'!F28)/ABS('Consolidated FS'!F28) -> -0.51330645 | G22: =('Consolidated FS'!H28-'Consolidated FS'!G28)/ABS('Consolidated FS'!G28) -> 0.79908865 | I22: =AVERAGE(D22:G22) -> 0.10105148 | J22: =MEDIAN(D22:G22) -> 0.059211871

Sheet FCFF
B2: Particulars | C2: 2021 | D2: 2022 | E2: 2023 | F2: 2024 | G2: 2025
B3: EBIT | C3: =Assumptions!C11 -> 5355.9 | D3: =Assumptions!D11 -> 6069.82 | E3: =Assumptions!E11 -> 5503.6 | F3: =Assumptions!F11 -> 2862.64 | G3: =Assumptions!G11 -> 5035.44
B4: Less: Tax on EBIT (25%) | C4: =25%*C3 -> 1338.975 | D4: =25%*D3 -> 1517.455 | E4: =25%*E3 -> 1375.9 | F4: =25%*F3 -> 715.66 | G4: =25%*G3 -> 1258.86
B5: NOPAT [EBIT × (1 − Tax)] | C5: =C3-C4 -> 4016.925 | D5: =D3-D4 -> 4552.365 | E5: =E3-E4 -> 4127.7 | F5: =F3-F4 -> 2146.98 | G5: =G3-G4 -> 3776.58
B6: Less: Net Capital Expenditure | D6: ='Fixed Asset Schedule'!D9 -> 146 | E6: ='Fixed Asset Schedule'!E9 -> 5766 | F6: ='Fixed Asset Schedule'!F9 -> 148 | G6: ='Fixed Asset Schedule'!G9 -> -1029
B7: Less: Change in Working Capital | D7: ='Changes in WC'!D7 -> 4166 | E7: ='Changes in WC'!E7 -> 643 | F7: ='Changes in WC'!F7 -> -867 | G7: ='Changes in WC'!G7 -> -479
B8: Reinvestment (Capex + ΔWCL) | C8: =SUM(C6:C7) -> 0 | D8: =SUM(D6:D7) -> 4312 | E8: =SUM(E6:E7) -> 6409 | F8: =SUM(F6:F7) -> -719 | G8: =SUM(G6:G7) -> -1508
B9: Free Cash Flow to Firm (FCFF) | C9: =C5-C8 -> 4016.925 | D9: =D5-D8 -> 240.365 | E9: =E5-E8 -> -2281.3 | F9: =F5-F8 -> 2865.98 | G9: =G5-G8 -> 5284.58
B11: Reinvestment Rate | D11: =D8/D5 -> 0.94719997 | E11: =E8/E5 -> 1.5526807 | F11: =F8/F5 -> -0.33488901 | G11: =G8/G5 -> -0.39930307
B13: Median Reinvestment rate /Sales percentage | C13: =MEDIAN(D11:G11) -> 0.30615548
B14: Average Reinvestment rate /Sales percentage | C14: =AVERAGE(D11:G11) -> 0.44142214

Sheet Fixed Asset Schedule
B2: Particulars | C2: 2021 | D2: 2022 | E2: 2023 | F2: 2024 | G2: 2025
B3: Beginning Balance (Net Fixed Assets) | D3: =C7 -> 8872 | E3: =D7 -> 9018 | F3: =E7 -> 14784 | G3: =F7 -> 14932
B4: Add: Net Purchases (Capex) | D4: =D5-D3 -> 1666 | E4: =E5-E3 -> 7723 | F4: =F5-F3 -> 1965 | G4: =G5-G3 -> 824
B5: Total Fixed Assets (Gross) | C5: =C6+C7 -> 10330 | D5: =D6+D7 -> 10538 | E5: =E6+E7 -> 16741 | F5: =F6+F7 -> 16749 | G5: =G6+G7 -> 15756
B6: Less: Depreciation & Amortisation | C6: =Assumptions!C10 -> 1458 | D6: =Assumptions!D10 -> 1520 | E6: =Assumptions!E10 -> 1957 | F6: =Assumptions!F10 -> 1817 | G6: =Assumptions!G10 -> 1853
B7: Closing Balance (Net Fixed Assets) | C7: ='Consolidated FS'!Q18 -> 8872 | D7: ='Consolidated FS'!R18 -> 9018 | E7: ='Consolidated FS'!S18 -> 14784 | F7: ='Consolidated FS'!T18 -> 14932 | G7: ='Consolidated FS'!U18 -> 13903
B9: Net Capital Expenditure | D9: =D4-D6 -> 146 | E9: =E4-E6 -> 5766 | F9: =F4-F6 -> 148 | G9: =G4-G6 -> -1029
B10: Net Capex / Sales (%) | D10: =D9/Assumptions!D3 -> 0.0032701698 | E10: =E9/Assumptions!E3 -> 0.10820041 | F10: =F9/Assumptions!F3 -> 0.0028463728 | G10: =G9/Assumptions!G3 -> -0.019419491
B12: Median Capital expenditure /Sales percentage | C12: =MEDIAN(D10:G10) -> 0.0030582713
B13: Average Capital expenditure /Sales percentage | C13: =AVERAGE(D10:G10) -> 0.023724366

Sheet Changes in WC
B2: Particulars | C2: 2021 | D2: 2022 | E2: 2023 | F2: 2024 | G2: 2025
B3: Inventories | C3: ='Consolidated FS'!R33 -> 24 | D3: ='Consolidated FS'!S33 -> 40 | E3: ='Consolidated FS'!T33 -> 24 | F3: ='Consolidated FS'!U33 -> 38 | G3: ='Consolidated FS'!V33 -> 39
B4: Trade Receivables | C4: ='Consolidated FS'!R34 -> 6473 | D4: ='Consolidated FS'!S34 -> 11933 | E4: ='Consolidated FS'!T34 -> 12882 | F4: ='Consolidated FS'!U34 -> 11401 | G4: ='Consolidated FS'!V34 -> 11547
B5: Trade Payables | C5: ='Consolidated FS'!R14 -> 2785 | D5: ='Consolidated FS'!S14 -> 4095 | E5: ='Consolidated FS'!T14 -> 4385 | F5: ='Consolidated FS'!U14 -> 3785 | G5: ='Consolidated FS'!V14 -> 4411
B6: Non-Cash Working Capital | C6: =C3+C4-C5 -> 3712 | D6: =D3+D4-D5 -> 7878 | E6: =E3+E4-E5 -> 8521 | F6: =F3+F4-F5 -> 7654 | G6: =G3+G4-G5 -> 7175
B7: Change in Working Capital | D7: =D6-C6 -> 4166 | E7: =E6-D6 -> 643 | F7: =F6-E6 -> -867 | G7: =G6-F6 -> -479
B8: Change in WC / Sales (%) | D8: =D7/Assumptions!D3 -> 0.093311831 | E8: =E7/Assumptions!E3 -> 0.012066054 | F8: =F7/Assumptions!F3 -> -0.01667436 | G8: =G7/Assumptions!G3 -> -0.0090397826
B10: Median Non-Cash WC / Sales (%) | C10: =MEDIAN(D8:G8) -> 0.0015131355
B11: Average Change in working capital / % of sales | C11: =AVERAGE(D8:G8) -> 0.019915936

Sheet Raw FSValuation
B2: S.No. | C2: Name | D2: CMP Rs. | E2: P/E | F2: Mar Cap Rs.Cr. | G2: Div Yld % | H2: NP Qtr Rs.Cr. | I2: Qtr Profit Var % | J2: ROCE % | K2: Debt Rs.Cr. | L2: EV / EBITDA | M2: No. Eq. Shares Cr. | N2: EBIT 12M Rs.Cr. | O2: NP Ann Rs.Cr. | P2: Sales Rs.Cr. | Q2: Cash End Rs.Cr.
B3: 1 | C3: TCS | D3: 2161.4 | E3: 14.95 | F3: 782013.44 | G3: 2.96 | H3: 13784 | I3: 12.22 | J3: 63.03 | K3: 11283 | L3: 10.21 | M3: 361.81 | N3: 70890 | O3: 49454 | P3: 267021 | Q3: 12908
B4: 2 | C4: Infosys | D4: 1116.4 | E4: 15.06 | F4: 452952.05 | G4: 4.3 | H4: 8509 | I4: 20.87 | J4: 39.95 | K4: 9176 | L4: 9.52 | M4: 405.73 | N4: 41324 | O4: 29474 | P4: 178650 | Q4: 22201
B5: 3 | C5: HCL Technologies | D5: 1109.6 | E5: 17.34 | F5: 301108.28 | G5: 4.87 | H5: 4490 | I5: 4.2 | J5: 30.6 | K5: 5215 | L5: 10 | M5: 271.37 | N5: 23927 | O5: 16652 | P5: 130144 | Q5: 23425
B6: 4 | C6: Wipro | D6: 180.14 | E6: 14.34 | F6: 189201.26 | G6: 6.11 | H6: 3521.6 | I6: -1.9 | J6: 17.88 | K6: 20291 | L6: 9.16 | M6: 1050.3 | N6: 18799.9 | O6: 13265.5 | P6: 92624 | Q6: 10555.5
B7: 5 | C7: Tech Mahindra | D7: 1429.2 | E7: 28.01 | F7: 140069.88 | G7: 3.57 | H7: 1356.4 | I7: 16.04 | J7: 23.14 | K7: 2186.2 | L7: 15.13 | M7: 98.01 | N7: 7182.9 | O7: 4805.5 | P7: 56815.4 | Q7: 5105.4
B8: 6 | C8: LTM | D8: 3844.7 | E8: 21.1 | F8: 114042 | G8: 1.95 | H8: 1387.3 | I8: 19.36 | J8: 29.6 | K8: 2310 | L8: 13.13 | M8: 29.66 | N8: 7595.5 | O8: 4982.7 | P8: 42307.6 | Q8: 2812.4
B9: 7 | C9: Persistent Systems | D9: 4811 | E9: 39.28 | F9: 75893.53 | G9: 0.73 | H9: 529.26 | I9: 33.73 | J9: 34.43 | K9: 477.45 | L9: 25.25 | M9: 15.78 | N9: 2572.92 | O9: 1865.12 | P9: 14748.45 | Q9: 1218.25
C10: Median: 66 Co. | D10: 292.68 | E10: 20.19 | F10: 1471.2 | G10: 0.49 | H10: 13.75 | I10: 18.53 | J10: 22.38 | K10: 43.27 | L10: 12.22 | M10: 7.35 | N10: 52.42 | O10: 34.75 | P10: 357.16 | Q10: 68.63

Sheet Relative Valuation
B2: Relative Valuation - Tech Mahindra Ltd
B3: Figures in Crore
B4: Comparable Company Valuation
B5: Company Name | C5: Market Data | J5: Financials | O5: Valuation
C6: No. of shares | D6: Share Price | E6: Equity value | F6: Debt | G6: cash | H6: Enterprises value | J6: Revenue | K6: EBITDA | L6: Net Profit | M6: EPS | O6: EV/Revenue | P6: EV/EBITDA | Q6: P/E Ratio
B7: TCS | C7: ='Raw FSValuation'!M3 -> 361.81 | D7: ='Raw FSValuation'!D3 -> 2161.4 | E7: =C7*D7 -> 782016.13 | F7: ='Raw FSValuation'!K3 -> 11283 | G7: ='Raw FSValuation'!Q3 -> 12908 | H7: =E7+F7-G7 -> 780391.13 | J7: ='Raw FSValuation'!P3 -> 267021 | K7: =H7/'Raw FSValuation'!L3 -> 76433.999 | L7: ='Raw FSValuation'!O3 -> 49454 | M7: =L7/C7 -> 136.685 | O7: =H7/J7 -> 2.9225834 | P7: =H7/K7 -> 10.21 | Q7: =D7/M7 -> 15.813001
B8: Infosys | C8: ='Raw FSValuation'!M4 -> 405.73 | D8: ='Raw FSValuation'!D4 -> 1116.4 | E8: =C8*D8 -> 452956.97 | F8: ='Raw FSValuation'!K4 -> 9176 | G8: ='Raw FSValuation'!Q4 -> 22201 | H8: =E8+F8-G8 -> 439931.97 | J8: ='Raw FSValuation'!P4 -> 178650 | K8: =H8/'Raw FSValuation'!L4 -> 46211.342 | L8: ='Raw FSValuation'!O4 -> 29474 | M8: =L8/C8 -> 72.644369 | O8: =H8/J8 -> 2.4625355 | P8: =H8/K8 -> 9.52 | Q8: =D8/M8 -> 15.368018
B9: HCL Technologies | C9: ='Raw FSValuation'!M5 -> 271.37 | D9: ='Raw FSValuation'!D5 -> 1109.6 | E9: =C9*D9 -> 301112.15 | F9: ='Raw FSValuation'!K5 -> 5215 | G9: ='Raw FSValuation'!Q5 -> 23425 | H9: =E9+F9-G9 -> 282902.15 | J9: ='Raw FSValuation'!P5 -> 130144 | K9: =H9/'Raw FSValuation'!L5 -> 28290.215 | L9: ='Raw FSValuation'!O5 -> 16652 | M9: =L9/C9 -> 61.362715 | O9: =H9/J9 -> 2.1737625 | P9: =H9/K9 -> 10 | Q9: =D9/M9 -> 18.082642
B10: Wipro | C10: ='Raw FSValuation'!M6 -> 1050.3 | D10: ='Raw FSValuation'!D6 -> 180.14 | E10: =C10*D10 -> 189201.04 | F10: ='Raw FSValuation'!K6 -> 20291 | G10: ='Raw FSValuation'!Q6 -> 10555.5 | H10: =E10+F10-G10 -> 198936.54 | J10: ='Raw FSValuation'!P6 -> 92624 | K10: =H10/'Raw FSValuation'!L6 -> 21717.963 | L10: ='Raw FSValuation'!O6 -> 13265.5 | M10: =L10/C10 -> 12.630201 | O10: =H10/J10 -> 2.1477861 | P10: =H10/K10 -> 9.16 | Q10: =D10/M10 -> 14.262639
B11: Tech Mahindra | C11: ='Raw FSValuation'!M7 -> 98.01 | D11: ='Raw FSValuation'!D7 -> 1429.2 | E11: =C11*D11 -> 140075.89 | F11: ='Raw FSValuation'!K7 -> 2186.2 | G11: ='Raw FSValuation'!Q7 -> 5105.4 | H11: =E11+F11-G11 -> 137156.69 | J11: ='Raw FSValuation'!P7 -> 56815.4 | K11: =H11/'Raw FSValuation'!L7 -> 9065.2143 | L11: ='Raw FSValuation'!O7 -> 4805.5 | M11: =L11/C11 -> 49.030711 | O11: =H11/J11 -> 2.414076 | P11: =H11/K11 -> 15.13 | Q11: =D11/M11 -> 29.149078
B12: LTM | C12: ='Raw FSValuation'!M8 -> 29.66 | D12: ='Raw FSValuation'!D8 -> 3844.7 | E12: =C12*D12 -> 114033.8 | F12: ='Raw FSValuation'!K8 -> 2310 | G12: ='Raw FSValuation'!Q8 -> 2812.4 | H12: =E12+F12-G12 -> 113531.4 | J12: ='Raw FSValuation'!P8 -> 42307.6 | K12: =H12/'Raw FSValuation'!L8 -> 8646.7176 | L12: ='Raw FSValuation'!O8 -> 4982.7 | M12: =L12/C12 -> 167.99393 | O12: =H12/J12 -> 2.6834754 | P12: =H12/K12 -> 13.13 | Q12: =D12/M12 -> 22.885946
B13: Persistent Systems | C13: ='Raw FSValuation'!M9 -> 15.78 | D13: ='Raw FSValuation'!D9 -> 4811 | E13: =C13*D13 -> 75917.58 | F13: ='Raw FSValuation'!K9 -> 477.45 | G13: ='Raw FSValuation'!Q9 -> 1218.25 | H13: =E13+F13-G13 -> 75176.78 | J13: ='Raw FSValuation'!P9 -> 14748.45 | K13: =H13/'Raw FSValuation'!L9 -> 2977.2982 | L13: ='Raw FSValuation'!O9 -> 1865.12 | M13: =L13/C13 -> 118.19518 | O13: =H13/J13 -> 5.0972665 | P13: =H13/K13 -> 25.25 | Q13: =D13/M13 -> 40.703858
B15: Particulars | C15: EV/Revenue | D15: EV/EBITDA | E15: P/E Ratio
B16: Implied Enterprise Value | C16: =J11*O19 -> 139909.94 | D16: =K11*P19 -> 92555.838 | E16: =L11*Q19 -> 86896.135 | M16: Median: 42 Co. | O16: =MAX(O7:O13) -> 5.0972665 | P16: =MAX(P7:P13) -> 25.25 | Q16: =MAX(Q7:Q13) -> 40.703858
B17: Net Debt | C17: =F11-G11 -> -2919.2 | D17: =C17 -> -2919.2 | E17: =D17 -> -2919.2 | M17: Max | O17: =QUARTILE(O7:O13,3) -> 2.8030294 | P17: =QUARTILE(P7:P13,3) -> 14.13 | Q17: =QUARTILE(Q7:Q13,3) -> 26.017512
B18: Implied Market Value | C18: =C16-C17 -> 142829.14 | D18: =D16-D17 -> 95475.038 | E18: =E16-E17 -> 89815.335 | M18: 75th Percentile | O18: =AVERAGE(O7:O13) -> 2.8430693 | P18: =AVERAGE(P7:P13) -> 13.2 | Q18: =AVERAGE(Q7:Q13) -> 22.323597
B19: Share Outstanding | C19: =C11 -> 98.01 | D19: =C19 -> 98.01 | E19: =D19 -> 98.01 | M19: Average | O19: =MEDIAN(O7:O13) -> 2.4625355 | P19: =MEDIAN(P7:P13) -> 10.21 | Q19: =MEDIAN(Q7:Q13) -> 18.082642
M20: median | O20: =QUARTILE(O7:O13,1) -> 2.2939193 | P20: =QUARTILE(P7:P13,1) -> 9.76 | Q20: =QUARTILE(Q7:Q13,1) -> 15.590509
B21: Implied Value per Share | C21: =C18/C19 -> 1457.2915 | D21: =D18/D19 -> 974.13568 | E21: =E18/E19 -> 916.38951 | M21: Min. | O21: =MIN(O7:O13) -> 2.1477861 | P21: =MIN(P7:P13) -> 9.16 | Q21: =MIN(Q7:Q13) -> 14.262639

Sheet Growth Scenerio
B2: Tech Mahindra Ltd "Growth Scenarios"
B4: Scenario 1: High Growth | O4: Average Of Revenue Growth | P4: =MEDIAN(Assumptions!D4:G4) -> 0.099236725
B5: INR Cr. | C5: LTM | D5: Y1E | E5: Y2E | F5: Y3E | G5: Y4W | H5: Y5E | I5: Y6E | J5: Y7E | K5: Y8E | L5: Y9E | M5: Y10E | O5: Risk free rate | P5: 0.067
B6: Sales | C6: =Assumptions!G3 -> 52988 | D6: =C6*(1+D7) -> 58246.356 | E6: =D6*(1+E7) -> 63817.903 | F6: =E6*(1+F7) -> 69693.809 | G6: =F6*(1+G7) -> 75861.095 | H6: =G6*(1+H7) -> 82302.407 | I6: =H6*(1+I7) -> 88995.85 | J6: =I6*(1+J7) -> 95914.884 | K6: =J6*(1+K7) -> 103028.29 | ... M6: =L6*(1+M7) -> 117690.33 | P6: =P4-P5 -> 0.032236725
B7: Sales Growth % | D7: =P4 -> 0.099236725 | E7: =D7-$P$7 -> 0.095654867 | F7: =E7-$P$7 -> 0.092073009 | G7: =F7-$P$7 -> 0.08849115 | H7: =G7-$P$7 -> 0.084909292 | I7: =H7-$P$7 -> 0.081327433 | J7: =I7-$P$7 -> 0.077745575 | K7: =J7-$P$7 -> 0.074163717 | L7: =K7-$P$7 -> 0.070581858 | M7: =L7-$P$7 -> 0.067 | O7: Per Year | P7: =P6/9 -> 0.0035818584
B10: Scenario 2: Average Growth | O10: Average Growth | P10: =Assumptions!C20 -> 0.091950798
B11: INR Cr. | C11: LTM | D11: Y1E | E11: Y2E | F11: Y3E | G11: Y4W | H11: Y5E | I11: Y6E | J11: Y7E | K11: Y8E | L11: Y9E | M11: Y10E | O11: Risk free rate | P11: 0.067
B12: Sales | C12: =C6 -> 52988 | D12: =C12*(1+D13) -> 57860.289 | E12: =D12*(1+E13) -> 63020.182 | F12: =E12*(1+F13) -> 68465.515 | G12: =F12*(1+G13) -> 74191.55 | H12: =G12*(1+H13) -> 80190.795 | I12: =H12*(1+I13) -> 86452.833 | J12: =I12*(1+J13) -> 92964.195 | K12: =J12*(1+K13) -> 99708.248 | ... M12: =L12*(1+M13) -> 113811.69 | P12: =P10-P11 -> 0.024950798
B13: Sales Growth % | D13: =P10 -> 0.091950798 | E13: =D13-$P$13 -> 0.089178487 | F13: =E13-$P$13 -> 0.086406176 | G13: =F13-$P$13 -> 0.083633865 | H13: =G13-$P$13 -> 0.080861554 | I13: =H13-$P$13 -> 0.078089243 | J13: =I13-$P$13 -> 0.075316933 | K13: =J13-$P$13 -> 0.072544622 | L13: =K13-$P$13 -> 0.069772311 | M13: =L13-$P$13 -> 0.067 | O13: Per Year | P13: =P12/9 -> 0.0027723109
B16: Scenario 3: EBIT Growth | O16: Growth in EBIT | P16: =Assumptions!C46 -> 0.034078657
B17: INR Cr. | C17: LTM | D17: Y1E | E17: Y2E | F17: Y3E | G17: Y4W | H17: Y5E | I17: Y6E | J17: Y7E | K17: Y8E | L17: Y9E | M17: Y10E | O17: Risk free rate | P17: 0.067
B18: Sales | C18: =C12 -> 52988 | D18: =C18*(1+D19) -> 54793.76 | E18: =D18*(1+E19) -> 56861.489 | F18: =E18*(1+F19) -> 59215.243 | G18: =F18*(1+G19) -> 61883.034 | H18: =G18*(1+H19) -> 64897.379 | I18: =H18*(1+I19) -> 68295.944 | J18: =I18*(1+J19) -> 72122.307 | K18: =J18*(1+K19) -> 76426.866 | ... M18: =L18*(1+M19) -> 86712.851 | P18: =P16-P17 -> -0.032921343
B19: Sales Growth % | D19: =P16 -> 0.034078657 | E19: =D19-$P$19 -> 0.037736584 | F19: =E19-$P$19 -> 0.041394511 | G19: =F19-$P$19 -> 0.045052438 | H19: =G19-$P$19 -> 0.048710365 | I19: =H19-$P$19 -> 0.052368292 | J19: =I19-$P$19 -> 0.056026219 | K19: =J19-$P$19 -> 0.059684146 | L19: =K19-$P$19 -> 0.063342073 | M19: =L19-$P$19 -> 0.067 | O19: Per Year | P19: =P18/9 -> -0.003657927
B21: Live Scenario | C21: 3
B22: INR Cr. | C22: LTM | D22: Y1E | E22: Y2E | F22: Y3E | G22: Y4W | H22: Y5E | I22: Y6E | J22: Y7E | K22: Y8E | L22: Y9E | M22: Y10E
B23: Sales | C23: =C6 -> 52988 | D23: =C23*(1+D24) -> 54793.76 | E23: =D23*(1+E24) -> 56861.489 | F23: =E23*(1+F24) -> 59215.243 | G23: =F23*(1+G24) -> 61883.034 | H23: =G23*(1+H24) -> 64897.379 | I23: =H23*(1+I24) -> 68295.944 | J23: =I23*(1+J24) -> 72122.307 | K23: =J23*(1+K24) -> 76426.866 | ... M23: =L23*(1+M24) -> 86712.851
B24: Sales Growth % | D24: =CHOOSE($C$21,D7,D13,D19) -> 0.034078657 | E24: =CHOOSE($C$21,E7,E13,E19) -> 0.037736584 | F24: =CHOOSE($C$21,F7,F13,F19) -> 0.041394511 | G24: =CHOOSE($C$21,G7,G13,G19) -> 0.045052438 | H24: =CHOOSE($C$21,H7,H13,H19) -> 0.048710365 | I24: =CHOOSE($C$21,I7,I13,I19) -> 0.052368292 | J24: =CHOOSE($C$21,J7,J13,J19) -> 0.056026219 | K24: =CHOOSE($C$21,K7,K13,K19) -> 0.059684146 | ... M24: =CHOOSE($C$21,M7,M13,M19) -> 0.067

Sheet DCF
B1: Tech Mahindra Ltd - "VALUATION"
D2: 1 | E2: 2 | F2: 3 | G2: 4 | H2: 5 | I2: 6 | J2: 7 | K2: 8 | L2: 9 | M2: 10
B3: INR Cr | C3: LTM | D3: Y1E | E3: Y2E | F3: Y3E | G3: Y4W | H3: Y5E | I3: Y6E | J3: Y7E | K3: Y8E | L3: Y9E | M3: Y10E | N3: Terminal Yr | P3: Terminal growth rate % | Q3: 0.05
B4: Sales | C4: ='Growth Scenerio'!C23 -> 52988 | D4: ='Growth Scenerio'!D23 -> 54793.76 | E4: ='Growth Scenerio'!E23 -> 56861.489 | F4: ='Growth Scenerio'!F23 -> 59215.243 | G4: ='Growth Scenerio'!G23 -> 61883.034 | H4: ='Growth Scenerio'!H23 -> 64897.379 | I4: ='Growth Scenerio'!I23 -> 68295.944 | J4: ='Growth Scenerio'!J23 -> 72122.307 | ... M4: ='Growth Scenerio'!M23 -> 86712.851 | N4: =M4*(1+Q3) -> 91048.494 | P4: Cost of Capital % | Q4: =Beta!K4*0.0744+0.067 -> 0.13314074
B5: Sales Growth | D5: ='Growth Scenerio'!D24 -> 0.034078657 | E5: ='Growth Scenerio'!E24 -> 0.037736584 | F5: ='Growth Scenerio'!F24 -> 0.041394511 | G5: ='Growth Scenerio'!G24 -> 0.045052438 | H5: ='Growth Scenerio'!H24 -> 0.048710365 | I5: ='Growth Scenerio'!I24 -> 0.052368292 | J5: ='Growth Scenerio'!J24 -> 0.056026219 | K5: ='Growth Scenerio'!K24 -> 0.059684146 | ... M5: ='Growth Scenerio'!M24 -> 0.067 | N5: =Q3 -> 0.05 | P5: Terminal reinvestment rate % | Q5: =Q3*Q4 -> 0.0066570369
B6: EBIT | D6: =D7*D4 -> 5816.9082 | E6: =E7*E4 -> 6036.4185 | F6: =F7*F4 -> 6286.2931 | G6: =G7*G4 -> 6569.5059 | H6: =H7*H4 -> 6889.5089 | I6: =I7*I4 -> 7250.3007 | J6: =J7*J4 -> 7656.5077 | K6: =K7*K4 -> 8113.4798 | ... N6: =N7*N4 -> 9665.7125
B7: EBIT Margin % | D7: =AVERAGE(Assumptions!$C$24:$G$24) -> 0.10616005 | E7: =AVERAGE(Assumptions!$C$24:$G$24) -> 0.10616005 | F7: =AVERAGE(Assumptions!$C$24:$G$24) -> 0.10616005 | G7: =AVERAGE(Assumptions!$C$24:$G$24) -> 0.10616005 | H7: =AVERAGE(Assumptions!$C$24:$G$24) -> 0.10616005 | I7: =AVERAGE(Assumptions!$C$24:$G$24) -> 0.10616005 | J7: =AVERAGE(Assumptions!$C$24:$G$24) -> 0.10616005 | K7: =AVERAGE(Assumptions!$C$24:$G$24) -> 0.10616005 | ... M7: =AVERAGE(Assumptions!$C$24:$G$24) -> 0.10616005 | N7: =M7 -> 0.10616005
B8: Less: Tax on EBIT | D8: =Assumptions!$C$30*D6 -> 1454.2271 | E8: =Assumptions!$C$30*E6 -> 1509.1046 | F8: =Assumptions!$C$30*F6 -> 1571.5733 | G8: =Assumptions!$C$30*G6 -> 1642.3765 | H8: =Assumptions!$C$30*H6 -> 1722.3772 | I8: =Assumptions!$C$30*I6 -> 1812.5752 | J8: =Assumptions!$C$30*J6 -> 1914.1269 | K8: =Assumptions!$C$30*K6 -> 2028.3699 | ... M8: =Assumptions!$C$30*M6 -> 2301.3601 | N8: =25%*N6 -> 2416.4281
B9: EBIT(1-T) | D9: =D6-D8 -> 4362.6812 | E9: =E6-E8 -> 4527.3138 | F9: =F6-F8 -> 4714.7198 | G9: =G6-G8 -> 4927.1294 | H9: =H6-H8 -> 5167.1317 | I9: =I6-I8 -> 5437.7255 | J9: =J6-J8 -> 5742.3807 | K9: =K6-K8 -> 6085.1098 | ... N9: =N6-N8 -> 7249.2844
B10: Less: Net Capital Expenditure | D10: ='Fixed Asset Schedule'!$C$12*D4 -> 167.57418 | E10: ='Fixed Asset Schedule'!$C$12*E4 -> 173.89786 | F10: ='Fixed Asset Schedule'!$C$12*F4 -> 181.09628 | G10: ='Fixed Asset Schedule'!$C$12*G4 -> 189.25511 | H10: ='Fixed Asset Schedule'!$C$12*H4 -> 198.47379 | I10: ='Fixed Asset Schedule'!$C$12*I4 -> 208.86752 | J10: ='Fixed Asset Schedule'!$C$12*J4 -> 220.56958 | K10: ='Fixed Asset Schedule'!$C$12*K4 -> 233.73409 | ... M10: ='Fixed Asset Schedule'!$C$12*M4 -> 265.19142
B11: Non Cash Working Capital | C11: ='Changes in WC'!G6 -> 7175 | D11: ='Changes in WC'!$C$10*D4 -> 82.910385 | E11: ='Changes in WC'!$C$10*E4 -> 86.03914 | F11: ='Changes in WC'!$C$10*F4 -> 89.600688 | G11: ='Changes in WC'!$C$10*G4 -> 93.637418 | H11: ='Changes in WC'!$C$10*H4 -> 98.19853 | I11: ='Changes in WC'!$C$10*I4 -> 103.34102 | J11: ='Changes in WC'!$C$10*J4 -> 109.13083 | K11: ='Changes in WC'!$C$10*K4 -> 115.64421 | ... M11: ='Changes in WC'!$C$10*M4 -> 131.2083
